Workbook

Sheet 使用说明
A1: 营业额自动导入 · 纯函数模板
A3: 使用方式
A5: 1. 在“营业额数据源”页，从第 4 行开始覆盖粘贴当月原稿数据；不要改动第 3 行表头。
A6: 2. 如有确认需保留的人工营业额，在“人工营业额覆盖”页维护五项键、营业额和原因。
A7: 3. 打开“各项指标明细（最终表）”：营业额列直接引用本文件数据源；新增窗口会自动追加在表格下方。
A8: 4. 打开“营业额导入核验”复核状态；点击“数据源行”可跳转到本文件内的源数据。
A9: 5. 核验通过后，使用“另存为”保存成当月目标文件。纯 Excel 函数无法自行另存为新文件。
A10: 6. 本模板不计算、不修改任何成本数据；仅管理营业额导入和核验。
A13: 环境要求：Microsoft 365 Excel（需支持 LET、XLOOKUP、FILTER、VSTACK、HSTACK、XMATCH）。

Sheet 各项指标明细（最终表）
A1: 2026年科桥餐饮公司各项指标明细
A2: 序号 | B2: 档口唯一标志 | C2: 分部名称 | D2: 项目代码 | E2: 项目名称 | F2: 项目类型 | G2: 核算会计 | H2: 分组作业名称 | I2: 分组作业窗口名称 | J2: 签订人 （会议纪要） | K2: 8月营业额 | L2: 目标值 | M2: 备注 | N2: 人员工资 | O2: 营业额指标 【部分金额折算成一年】 | P2: 服务费 | Q2: 服务费金额 | R2: 服务费项目填写当月实际金额 | S2: 服务费差异 | T2: 虫害消杀 | U2: 虫害消杀金额 | V2: 虫害消杀项目填写当月实际金额 | W2: 虫害消杀差异 | X2: 采购费 | Y2: 采购费金额 | Z2: 采购费项目填写当月实际金额 | AA2: 采购费差异 | AB2: 装修折旧 | AC2: 装修折旧金额 | AD2: 装修折旧项目填写当月实际金额 | AE2: 装修折旧差异 | AF2: 管理人员 | AG2: 管理人员金额 | AH2: 管理人员项目填写当月实际金额 | AI2: 管理人员差异 | AJ2: 共建活动 | AK2: 共建活动金额 | AL2: 共建活动项目填写当月实际金额 | AM2: 共建活动差异 | AN2: 资产 | AO2: 资产金额 | AP2: 资产项目填写当月实际金额 | AQ2: 资产差异 | AR2: 卫生费 | AS2: 卫生费金额 | AT2: 卫生费项目填写当月实际金额 | AU2: 卫生费差异 | AV2: 能源费 | AW2: 能源费金额 | AX2: 能源费项目填写当月实际金额 | AY2: 能源费差异 | AZ2: 其他 | BA2: 其他金额 | BB2: 其他项目填写当月实际金额米饭差价 | BC2: 其他差异 | BD2: 其他费用1 | BE2: 其他费用1金额 | BF2: 其他费用1项目填写当月实际金额 | BG2: 其他费用1差异 | BH2: 其他费用2 | BI2: 其他费用2金额 | BJ2: 其他费用2项目填写当月实际金额 | BK2: 其他费用2差异 | BL2: 原材料比例 | BM2: 原材料金额 | BN2: 原材料项目填写当月实际金额 | BO2: 原材料差异 | BP2: 成本费用合计金额 | BQ2: 项目填写成本费用合计 | BR2: 差异合计 | BS2: 分部管理费 （按实+固定值） | BT2: 业务费 | BU2: 备注1 | BV2: 备注2
A3: 4 | B3: KQCY0004 | C3: 餐饮一分部 | D3: CF751 | E3: 国防科大（长沙）食堂 | F3: 人员服务外包 | G3: 徐敏捷 | H3: / | I3: / | J3: / | K3: =LET(k,D3&"|"&E3&"|"&H3&"|"&I3&"|"&J3,sk,tblRevenueInput[项目代码]&"|"&tblRevenueInput[项目名称]&"|"&tblRevenueInput[分组作业名称]&"|"&tblRevenueInput[分组作业窗口名称]&"|"&tblRevenueInput[签订人],ok,tblRevenueOverride[项目代码]&"|"&tblRevenueOverride[项目名称]&"|"&tblRevenueOverride[分组作业名称]&"|"&tblRevenueOverride[分组作业窗口名称]&"|"&tblRevenueOverride[责任人],ov,IFERROR(XLOOKUP(k,ok,tblRevenueOverride[营业额覆盖],""),""),IF(ov<>"",ov,IFERROR(XLOOKUP(k,sk,tblRevenueInput[全额营业额合计],""),""))) | O3: 8931000 | P3: 0 | Q3: =K3*P3 | S3: =Q3-R3 | T3: 0 | U3: =K3*T3 | W3: =U3-V3 | X3: 0 | Y3: =K3*X3 | AA3: =Y3-Z3 | AB3: 0 | AC3: =K3*AB3 | AE3: =AC3-AD3 | AF3: 0 | AG3: =K3*AF3 | AI3: =AG3-AH3 | AJ3: 0 | AK3: =K3*AJ3 | AM3: =AK3-AL3 | AN3: 0 | AO3: =K3*AN3 | AQ3: =AO3-AP3 | AR3: 0 | AS3: =K3*AR3 | AU3: =AS3-AT3 | AV3: 0 | AW3: =K3*AV3 | AY3: =AW3-AX3 | AZ3: 0 | BA3: =K3*AZ3 | BC3: =BA3-BB3 | BE3: =K3*BD3 | BG3: =BE3-BF3 | BI3: =K3*BH3 | BK3: =BI3-BJ3 | BL3: 0 | BM3: =K3*BL3 | BO3: =BM3-BN3 | BP3: =N3+Q3+U3+Y3+AC3+AG3+AK3+AO3+AS3+AW3+BA3+BE3+BI3+BM3 | BQ3: =N3+R3+V3+Z3+AD3+AH3+AL3+AP3+AT3+AX3+BB3+BF3+BJ3+BN3 | BR3: =BP3-BQ3 | BS3: 0.045 | BT3: /
A4: 6 | B4: KQCY0006 | C4: 餐饮一分部 | D4: CF474 | E4: 安工大七食堂 | F4: 强责 | G4: 卫屹 | H4: 第一班组 | I4: 手工馄饨（大陷水饺、刀削面/汆肉米线） | J4: 潘海英 | K4: =LET(k,D4&"|"&E4&"|"&H4&"|"&I4&"|"&J4,sk,tblRevenueInput[项目代码]&"|"&tblRevenueInput[项目名称]&"|"&tblRevenueInput[分组作业名称]&"|"&tblRevenueInput[分组作业窗口名称]&"|"&tblRevenueInput[签订人],ok,tblRevenueOverride[项目代码]&"|"&tblRevenueOverride[项目名称]&"|"&tblRevenueOverride[分组作业名称]&"|"&tblRevenueOverride[分组作业窗口名称]&"|"&tblRevenueOverride[责任人],ov,IFERROR(XLOOKUP(k,ok,tblRevenueOverride[营业额覆盖],""),""),IF(ov<>"",ov,IFERROR(XLOOKUP(k,sk,tblRevenueInput[全额营业额合计],""),""))) | O4: 700000 | P4: 0.07 | Q4: =K4*P4 | S4: =Q4-R4 | T4: 0.01 | U4: =K4*T4 | W4: =U4-V4 | X4: 0 | Y4: =K4*X4 | AA4: =Y4-Z4 | AB4: 0.03 | AC4: =K4*AB4 | AE4: =AC4-AD4 | AF4: 0.03 | AG4: =K4*AF4 | AI4: =AG4-AH4 | AJ4: 0.01 | AK4: =K4*AJ4 | AM4: =AK4-AL4 | AN4: 0.02 | AO4: =K4*AN4 | AQ4: =AO4-AP4 | AR4: 0.04 | AS4: =K4*AR4 | AU4: =AS4-AT4 | AV4: 0.05 | AW4: =K4*AV4 | AY4: =AW4-AX4 | AZ4: 按实 | BA4: =BB4 | BC4: =BA4-BB4 | BD4: 0 | BE4: =K4*BD4 | BG4: =BE4-BF4 | BH4: 0 | BI4: =K4*BH4 | BK4: =BI4-BJ4 | BL4: 按实 | BM4: =BN4 | BO4: =BM4-BN4 | BP4: =N4+Q4+U4+Y4+AC4+AG4+AK4+AO4+AS4+AW4+BA4+BE4+BI4+BM4 | BQ4: =N4+R4+V4+Z4+AD4+AH4+AL4+AP4+AT4+AX4+BB4+BF4+BJ4+BN4 | BR4: =BP4-BQ4 | BS4: / | BT4: / | BU4: 1、甲方管理费：乙方自愿向甲方缴纳考核奖励资金，费用金额为29.5万元/年。一年按照10个月计算(2、8月份不计)，每月从餐厅营业款中扣除。服务费包含未拆分 2、甲方捐赠：助学基金5000元。服务费包含未拆分 3、原材料：安徽工业大学食堂食品原材料定点采购办法约定食品原材料≥55%营业额（不含一次性打包用品）
A5: 7 | B5: KQCY0007 | C5: 餐饮一分部 | D5: CF474 | E5: 安工大七食堂 | F5: 强责 | G5: 卫屹 | H5: 第二班组 | I5: 黄焖系列（酸菜肉煲系列、椒麻鸡系列、酸菜鱼系列） | J5: 胡科才 | K5: =LET(k,D5&"|"&E5&"|"&H5&"|"&I5&"|"&J5,sk,tblRevenueInput[项目代码]&"|"&tblRevenueInput[项目名称]&"|"&tblRevenueInput[分组作业名称]&"|"&tblRevenueInput[分组作业窗口名称]&"|"&tblRevenueInput[签订人],ok,tblRevenueOverride[项目代码]&"|"&tblRevenueOverride[项目名称]&"|"&tblRevenueOverride[分组作业名称]&"|"&tblRevenueOverride[分组作业窗口名称]&"|"&tblRevenueOverride[责任人],ov,IFERROR(XLOOKUP(k,ok,tblRevenueOverride[营业额覆盖],""),""),IF(ov<>"",ov,IFERROR(XLOOKUP(k,sk,tblRevenueInput[全额营业额合计],""),""))) | O5: 500000 | P5: 0.07 | Q5: =K5*P5 | S5: =Q5-R5 | T5: 0.01 | U5: =K5*T5 | W5: =U5-V5 | X5: 0 | Y5: =K5*X5 | AA5: =Y5-Z5 | AB5: 0.03 | AC5: =K5*AB5 | AE5: =AC5-AD5 | AF5: 0.03 | AG5: =K5*AF5 | AI5: =AG5-AH5 | AJ5: 0.01 | AK5: =K5*AJ5 | AM5: =AK5-AL5 | AN5: 0.02 | AO5: =K5*AN5 | AQ5: =AO5-AP5 | AR5: 0.04 | AS5: =K5*AR5 | AU5: =AS5-AT5 | AV5: 0.05 | AW5: =K5*AV5 | AY5: =AW5-AX5 | AZ5: 按实 | BA5: =BB5 | BC5: =BA5-BB5 | BD5: 0 | BE5: =K5*BD5 | BG5: =BE5-BF5 | BH5: 0 | BI5: =K5*BH5 | BK5: =BI5-BJ5 | BL5: 按实 | BM5: =BN5 | BO5: =BM5-BN5 | BP5: =N5+Q5+U5+Y5+AC5+AG5+AK5+AO5+AS5+AW5+BA5+BE5+BI5+BM5 | BQ5: =N5+R5+V5+Z5+AD5+AH5+AL5+AP5+AT5+AX5+BB5+BF5+BJ5+BN5 | BR5: =BP5-BQ5 | BS5: / | BT5: / | BU5: 1、甲方管理费：乙方自愿向甲方缴纳考核奖励资金，费用金额为29.5万元/年。一年按照10个月计算(2、8月份不计)，每月从餐厅营业款中扣除。服务费包含未拆分 2、甲方捐赠：助学基金5000元。服务费包含未拆分 3、原材料：安徽工业大学食堂食品原材料定点采购办法约定食品原材料≥55%营业额（不含一次性打包用品）
A6: 8 | B6: KQCY0008 | C6: 餐饮一分部 | D6: CF474 | E6: 安工大七食堂 | F6: 强责 | G6: 卫屹 | H6: 第三班组 | I6: 猪脚饭系列（套饭系列、菜饭骨头汤系列） | J6: 杨克顺 | K6: =LET(k,D6&"|"&E6&"|"&H6&"|"&I6&"|"&J6,sk,tblRevenueInput[项目代码]&"|"&tblRevenueInput[项目名称]&"|"&tblRevenueInput[分组作业名称]&"|"&tblRevenueInput[分组作业窗口名称]&"|"&tblRevenueInput[签订人],ok,tblRevenueOverride[项目代码]&"|"&tblRevenueOverride[项目名称]&"|"&tblRevenueOverride[分组作业名称]&"|"&tblRevenueOverride[分组作业窗口名称]&"|"&tblRevenueOverride[责任人],ov,IFERROR(XLOOKUP(k,ok,tblRevenueOverride[营业额覆盖],""),""),IF(ov<>"",ov,IFERROR(XLOOKUP(k,sk,tblRevenueInput[全额营业额合计],""),""))) | N6: 3866 | O6: 700000 | P6: 0.07 | Q6: =K6*P6 | S6: =Q6-R6 | T6: 0.01 | U6: =K6*T6 | W6: =U6-V6 | X6: 0 | Y6: =K6*X6 | AA6: =Y6-Z6 | AB6: 0.03 | AC6: =K6*AB6 | AE6: =AC6-AD6 | AF6: 0.03 | AG6: =K6*AF6 | AI6: =AG6-AH6 | AJ6: 0.01 | AK6: =K6*AJ6 | AM6: =AK6-AL6 | AN6: 0.02 | AO6: =K6*AN6 | AQ6: =AO6-AP6 | AR6: 0.04 | AS6: =K6*AR6 | AU6: =AS6-AT6 | AV6: 0.05 | AW6: =K6*AV6 | AY6: =AW6-AX6 | AZ6: 按实 | BA6: =BB6 | BC6: =BA6-BB6 | BD6: 0 | BE6: =K6*BD6 | BG6: =BE6-BF6 | BH6: 0 | BI6: =K6*BH6 | BK6: =BI6-BJ6 | BL6: 按实 | BM6: =BN6 | BO6: =BM6-BN6 | BP6: =N6+Q6+U6+Y6+AC6+AG6+AK6+AO6+AS6+AW6+BA6+BE6+BI6+BM6 | BQ6: =N6+R6+V6+Z6+AD6+AH6+AL6+AP6+AT6+AX6+BB6+BF6+BJ6+BN6 | BR6: =BP6-BQ6 | BS6: / | BT6: / | BU6: 1、甲方管理费：乙方自愿向甲方缴纳考核奖励资金，费用金额为29.5万元/年。一年按照10个月计算(2、8月份不计)，每月从餐厅营业款中扣除。服务费包含未拆分 2、甲方捐赠：助学基金5000元。服务费包含未拆分 3、原材料：安徽工业大学食堂食品原材料定点采购办法约定食品原材料≥55%营业额（不含一次性打包用品）
A7: 9 | B7: KQCY0009 | C7: 餐饮一分部 | D7: CF474 | E7: 安工大七食堂 | F7: 强责 | G7: 卫屹 | H7: 第四班组 | I7: 拌饭系列（肉夹馍、紫菜包饭） | J7: 魏祖华 | K7: =LET(k,D7&"|"&E7&"|"&H7&"|"&I7&"|"&J7,sk,tblRevenueInput[项目代码]&"|"&tblRevenueInput[项目名称]&"|"&tblRevenueInput[分组作业名称]&"|"&tblRevenueInput[分组作业窗口名称]&"|"&tblRevenueInput[签订人],ok,tblRevenueOverride[项目代码]&"|"&tblRevenueOverride[项目名称]&"|"&tblRevenueOverride[分组作业名称]&"|"&tblRevenueOverride[分组作业窗口名称]&"|"&tblRevenueOverride[责任人],ov,IFERROR(XLOOKUP(k,ok,tblRevenueOverride[营业额覆盖],""),""),IF(ov<>"",ov,IFERROR(XLOOKUP(k,sk,tblRevenueInput[全额营业额合计],""),""))) | O7: 700000 | P7: 0.07 | Q7: =K7*P7 | R7: 279.09 | S7: =Q7-R7 | T7: 0.01 | U7: =K7*T7 | V7: 39.87 | W7: =U7-V7 | X7: 0 | Y7: =K7*X7 | Z7: 0 | AA7: =Y7-Z7 | AB7: 0.03 | AC7: =K7*AB7 | AD7: 119.61 | AE7: =AC7-AD7 | AF7: 0.03 | AG7: =K7*AF7 | AH7: 119.61 | AI7: =AG7-AH7 | AJ7: 0.01 | AK7: =K7*AJ7 | AL7: 39.87 | AM7: =AK7-AL7 | AN7: 0.02 | AO7: =K7*AN7 | AP7: 79.74 | AQ7: =AO7-AP7 | AR7: 0.04 | AS7: =K7*AR7 | AT7: 159.48 | AU7: =AS7-AT7 | AV7: 0.05 | AW7: =K7*AV7 | AX7: 199.35 | AY7: =AW7-AX7 | AZ7: 按实 | BA7: =BB7 | BB7: 0 | BC7: =BA7-BB7 | BD7: 0 | BE7: =K7*BD7 | BF7: 0 | BG7: =BE7-BF7 | BH7: 0 | BI7: =K7*BH7 | BJ7: 0 | BK7: =BI7-BJ7 | BL7: 按实 | BM7: =BN7 | BN7: 0 | BO7: =BM7-BN7 | BP7: =N7+Q7+U7+Y7+AC7+AG7+AK7+AO7+AS7+AW7+BA7+BE7+BI7+BM7 | BQ7: =N7+R7+V7+Z7+AD7+AH7+AL7+AP7+AT7+AX7+BB7+BF7+BJ7+BN7 | BR7: =BP7-BQ7 | BS7: / | BT7: / | BU7: 1、甲方管理费：乙方自愿向甲方缴纳考核奖励资金，费用金额为29.5万元/年。一年按照10个月计算(2、8月份不计)，每月从餐厅营业款中扣除。服务费包含未拆分 2、甲方捐赠：助学基金5000元。服务费包含未拆分 3、原材料：安徽工业大学食堂食品原材料定点采购办法约定食品原材料≥55%营业额（不含一次性打包用品）
A8: 11 | B8: KQCY0011 | C8: 餐饮一分部 | D8: CF477 | E8: 上海民航第一食堂 | F8: 分组作业 | G8: 卫屹 | H8: 第二班组 | I8: 山东煎饼 | J8: 姚群 | K8: =LET(k,D8&"|"&E8&"|"&H8&"|"&I8&"|"&J8,sk,tblRevenueInput[项目代码]&"|"&tblRevenueInput[项目名称]&"|"&tblRevenueInput[分组作业名称]&"|"&tblRevenueInput[分组作业窗口名称]&"|"&tblRevenueInput[签订人],ok,tblRevenueOverride[项目代码]&"|"&tblRevenueOverride[项目名称]&"|"&tblRevenueOverride[分组作业名称]&"|"&tblRevenueOverride[分组作业窗口名称]&"|"&tblRevenueOverride[责任人],ov,IFERROR(XLOOKUP(k,ok,tblRevenueOverride[营业额覆盖],""),""),IF(ov<>"",ov,IFERROR(XLOOKUP(k,sk,tblRevenueInput[全额营业额合计],""),""))) | O8: 570000 | P8: 0.1 | Q8: =K8*P8 | S8: =Q8-R8 | T8: 0.03 | U8: =K8*T8 | W8: =U8-V8 | X8: 0 | Y8: =K8*X8 | AA8: =Y8-Z8 | AB8: 0.05 | AC8: =K8*AB8 | AE8: =AC8-AD8 | AF8: 0.02 | AG8: =K8*AF8 | AI8: =AG8-AH8 | AJ8: 0 | AK8: =K8*AJ8 | AM8: =AK8-AL8 | AN8: 0.03 | AO8: =K8*AN8 | AQ8: =AO8-AP8 | AR8: 0 | AS8: =K8*AR8 | AU8: =AS8-AT8 | AV8: 0.04 | AW8: =K8*AV8 | AY8: =AW8-AX8 | AZ8: 按实 | BA8: =BB8 | BC8: =BA8-BB8 | BD8: 0 | BE8: =K8*BD8 | BG8: =BE8-BF8 | BH8: 0 | BI8: =K8*BH8 | BK8: =BI8-BJ8 | BL8: 按实 | BM8: =BN8 | BO8: =BM8-BN8 | BP8: =N8+Q8+U8+Y8+AC8+AG8+AK8+AO8+AS8+AW8+BA8+BE8+BI8+BM8 | BQ8: =N8+R8+V8+Z8+AD8+AH8+AL8+AP8+AT8+AX8+BB8+BF8+BJ8+BN8 | BR8: =BP8-BQ8 | BS8: / | BT8: / | BU8: 1、服务费：包含卫生费，不单独分摊
A9: 12 | B9: KQCY0012 | C9: 餐饮一分部 | D9: CF477 | E9: 上海民航第一食堂 | F9: 分组作业 | G9: 卫屹 | H9: 第六班组 | I9: 蜜雪冰城 | J9: 任黎明 | K9: =LET(k,D9&"|"&E9&"|"&H9&"|"&I9&"|"&J9,sk,tblRevenueInput[项目代码]&"|"&tblRevenueInput[项目名称]&"|"&tblRevenueInput[分组作业名称]&"|"&tblRevenueInput[分组作业窗口名称]&"|"&tblRevenueInput[签订人],ok,tblRevenueOverride[项目代码]&"|"&tblRevenueOverride[项目名称]&"|"&tblRevenueOverride[分组作业名称]&"|"&tblRevenueOverride[分组作业窗口名称]&"|"&tblRevenueOverride[责任人],ov,IFERROR(XLOOKUP(k,ok,tblRevenueOverride[营业额覆盖],""),""),IF(ov<>"",ov,IFERROR(XLOOKUP(k,sk,tblRevenueInput[全额营业额合计],""),""))) | O9: 899800 | P9: 0 | Q9: =K9*P9 | S9: =Q9-R9 | T9: 0 | U9: =K9*T9 | W9: =U9-V9 | X9: 0 | Y9: =K9*X9 | AA9: =Y9-Z9 | AB9: 0 | AC9: =K9*AB9 | AE9: =AC9-AD9 | AF9: 0 | AG9: =K9*AF9 | AI9: =AG9-AH9 | AJ9: 0 | AK9: =K9*AJ9 | AM9: =AK9-AL9 | AN9: 0 | AO9: =K9*AN9 | AQ9: =AO9-AP9 | AR9: 0 | AS9: =K9*AR9 | AU9: =AS9-AT9 | AV9: 0 | AW9: =K9*AV9 | AY9: =AW9-AX9 | AZ9: 按实 | BA9: =BB9 | BC9: =BA9-BB9 | BD9: 16万元/年，3月-9月、9月-12月分8个月收取，每月收取20000元 | BE9: =BF9 | BF9: 0 | BG9: =BE9-BF9 | BH9: 0 | BI9: =K9*BH9 | BK9: =BI9-BJ9 | BL9: 按实 | BM9: =BN9 | BO9: =BM9-BN9 | BP9: =N9+Q9+U9+Y9+AC9+AG9+AK9+AO9+AS9+AW9+BA9+BE9+BI9+BM9 | BQ9: =N9+R9+V9+Z9+AD9+AH9+AL9+AP9+AT9+AX9+BB9+BF9+BJ9+BN9 | BR9: =BP9-BQ9 | BS9: / | BT9: / | BU9: 1、其他：固定资金16万元/年，3月-9月、9月-12月分8个月收取，每月收取20000元
A10: 13 | B10: KQCY0013 | C10: 餐饮一分部 | D10: CF477 | E10: 上海民航第一食堂 | F10: 分组作业 | G10: 卫屹 | H10: 第三班组 | I10: 糖水粥铺 | J10: 孙青青 | K10: =LET(k,D10&"|"&E10&"|"&H10&"|"&I10&"|"&J10,sk,tblRevenueInput[项目代码]&"|"&tblRevenueInput[项目名称]&"|"&tblRevenueInput[分组作业名称]&"|"&tblRevenueInput[分组作业窗口名称]&"|"&tblRevenueInput[签订人],ok,tblRevenueOverride[项目代码]&"|"&tblRevenueOverride[项目名称]&"|"&tblRevenueOverride[分组作业名称]&"|"&tblRevenueOverride[分组作业窗口名称]&"|"&tblRevenueOverride[责任人],ov,IFERROR(XLOOKUP(k,ok,tblRevenueOverride[营业额覆盖],""),""),IF(ov<>"",ov,IFERROR(XLOOKUP(k,sk,tblRevenueInput[全额营业额合计],""),""))) | O10: 449900 | P10: 0.1 | Q10: =K10*P10 | S10: =Q10-R10 | T10: 0.03 | U10: =K10*T10 | W10: =U10-V10 | X10: 0 | Y10: =K10*X10 | AA10: =Y10-Z10 | AB10: 0.05 | AC10: =K10*AB10 | AE10: =AC10-AD10 | AF10: 0.02 | AG10: =K10*AF10 | AI10: =AG10-AH10 | AJ10: 0 | AK10: =K10*AJ10 | AM10: =AK10-AL10 | AN10: 0.03 | AO10: =K10*AN10 | AQ10: =AO10-AP10 | AR10: 0 | AS10: =K10*AR10 | AU10: =AS10-AT10 | AV10: 0.04 | AW10: =K10*AV10 | AY10: =AW10-AX10 | AZ10: 按实 | BA10: =BB10 | BC10: =BA10-BB10 | BD10: 0 | BE10: =K10*BD10 | BG10: =BE10-BF10 | BH10: 0 | BI10: =K10*BH10 | BK10: =BI10-BJ10 | BL10: 按实 | BM10: =BN10 | BO10: =BM10-BN10 | BP10: =N10+Q10+U10+Y10+AC10+AG10+AK10+AO10+AS10+AW10+BA10+BE10+BI10+BM10 | BQ10: =N10+R10+V10+Z10+AD10+AH10+AL10+AP10+AT10+AX10+BB10+BF10+BJ10+BN10 | BR10: =BP10-BQ10 | BS10: / | BT10: / | BU10: 1、服务费：包含卫生费，不单独分摊
A11: 14 | B11: KQCY0014 | C11: 餐饮一分部 | D11: CF477 | E11: 上海民航第一食堂 | F11: 分组作业 | G11: 卫屹 | H11: 第四班组 | I11: 大碗面 | J11: 景帅帅 | K11: =LET(k,D11&"|"&E11&"|"&H11&"|"&I11&"|"&J11,sk,tblRevenueInput[项目代码]&"|"&tblRevenueInput[项目名称]&"|"&tblRevenueInput[分组作业名称]&"|"&tblRevenueInput[分组作业窗口名称]&"|"&tblRevenueInput[签订人],ok,tblRevenueOverride[项目代码]&"|"&tblRevenueOverride[项目名称]&"|"&tblRevenueOverride[分组作业名称]&"|"&tblRevenueOverride[分组作业窗口名称]&"|"&tblRevenueOverride[责任人],ov,IFERROR(XLOOKUP(k,ok,tblRevenueOverride[营业额覆盖],""),""),IF(ov<>"",ov,IFERROR(XLOOKUP(k,sk,tblRevenueInput[全额营业额合计],""),""))) | N11: 20030.94 | O11: 486500 | P11: 0.1 | Q11: =K11*P11 | S11: =Q11-R11 | T11: 0.03 | U11: =K11*T11 | V11: 0 | W11: =U11-V11 | X11: 0 | Y11: =K11*X11 | Z11: 0 | AA11: =Y11-Z11 | AB11: 0.05 | AC11: =K11*AB11 | AD11: 0 | AE11: =AC11-AD11 | AF11: 0.02 | AG11: =K11*AF11 | AH11: 0 | AI11: =AG11-AH11 | AJ11: 0 | AK11: =K11*AJ11 | AL11: 0 | AM11: =AK11-AL11 | AN11: 0.03 | AO11: =K11*AN11 | AP11: 0 | AQ11: =AO11-AP11 | AR11: 0 | AS11: =K11*AR11 | AT11: 0 | AU11: =AS11-AT11 | AV11: 0.04 | AW11: =K11*AV11 | AX11: 0 | AY11: =AW11-AX11 | AZ11: 按实 | BA11: =BB11 | BB11: 0 | BC11: =BA11-BB11 | BD11: 0 | BE11: =K11*BD11 | BF11: 0 | BG11: =BE11-BF11 | BH11: 0 | BI11: =K11*BH11 | BJ11: 0 | BK11: =BI11-BJ11 | BL11: 按实 | BM11: =BN11 | BN11: 0 | BO11: =BM11-BN11 | BP11: =N11+Q11+U11+Y11+AC11+AG11+AK11+AO11+AS11+AW11+BA11+BE11+BI11+BM11 | BQ11: =N11+R11+V11+Z11+AD11+AH11+AL11+AP11+AT11+AX11+BB11+BF11+BJ11+BN11 | BR11: =BP11-BQ11 | BS11: / | BT11: / | BU11: 1、服务费：包含卫生费，不单独分摊
A12: 15 | B12: KQCY0015 | C12: 餐饮一分部 | D12: CF477 | E12: 上海民航第一食堂 | F12: 分组作业 | G12: 卫屹 | H12: 第一班组 | I12: 早餐 | J12: 芦磊 | K12: =LET(k,D12&"|"&E12&"|"&H12&"|"&I12&"|"&J12,sk,tblRevenueInput[项目代码]&"|"&tblRevenueInput[项目名称]&"|"&tblRevenueInput[分组作业名称]&"|"&tblRevenueInput[分组作业窗口名称]&"|"&tblRevenueInput[签订人],ok,tblRevenueOverride[项目代码]&"|"&tblRevenueOverride[项目名称]&"|"&tblRevenueOverride[分组作业名称]&"|"&tblRevenueOverride[分组作业窗口名称]&"|"&tblRevenueOverride[责任人],ov,IFERROR(XLOOKUP(k,ok,tblRevenueOverride[营业额覆盖],""),""),IF(ov<>"",ov,IFERROR(XLOOKUP(k,sk,tblRevenueInput[全额营业额合计],""),""))) | O12: 628600 | P12: 0.1 | Q12: =K12*P12 | R12: 0 | S12: =Q12-R12 | T12: 0.03 | U12: =K12*T12 | W12: =U12-V12 | X12: 0 | Y12: =K12*X12 | AA12: =Y12-Z12 | AB12: 0.05 | AC12: =K12*AB12 | AE12: =AC12-AD12 | AF12: 0.02 | AG12: =K12*AF12 | AI12: =AG12-AH12 | AJ12: 0 | AK12: =K12*AJ12 | AM12: =AK12-AL12 | AN12: 0.03 | AO12: =K12*AN12 | AQ12: =AO12-AP12 | AR12: 0 | AS12: =K12*AR12 | AU12: =AS12-AT12 | AV12: 0 | AW12: =K12*AV12 | AY12: =AW12-AX12 | AZ12: 按实 | BA12: =BB12 | BC12: =BA12-BB12 | BD12: 0 | BE12: =K12*BD12 | BG12: =BE12-BF12 | BH12: 0 | BI12: =K12*BH12 | BK12: =BI12-BJ12 | BL12: 按实 | BM12: =BN12 | BO12: =BM12-BN12 | BP12: =N12+Q12+U12+Y12+AC12+AG12+AK12+AO12+AS12+AW12+BA12+BE12+BI12+BM12 | BQ12: =N12+R12+V12+Z12+AD12+AH12+AL12+AP12+AT12+AX12+BB12+BF12+BJ12+BN12 | BR12: =BP12-BQ12 | BS12: / | BT12: / | BU12: 1、服务费：包含卫生费、能源费，不单独分摊
A13: 16 | B13: KQCY0016 | C13: 餐饮一分部 | D13: CF272 | E13: 苏州工学院南一食堂 | F13: 强责 | G13: 郑虎 | H13: / | I13: / | J13: / | K13: =LET(k,D13&"|"&E13&"|"&H13&"|"&I13&"|"&J13,sk,tblRevenueInput[项目代码]&"|"&tblRevenueInput[项目名称]&"|"&tblRevenueInput[分组作业名称]&"|"&tblRevenueInput[分组作业窗口名称]&"|"&tblRevenueInput[签订人],ok,tblRevenueOverride[项目代码]&"|"&tblRevenueOverride[项目名称]&"|"&tblRevenueOverride[分组作业名称]&"|"&tblRevenueOverride[分组作业窗口名称]&"|"&tblRevenueOverride[责任人],ov,IFERROR(XLOOKUP(k,ok,tblRevenueOverride[营业额覆盖],""),""),IF(ov<>"",ov,IFERROR(XLOOKUP(k,sk,tblRevenueInput[全额营业额合计],""),""))) | O13: 0 | P13: 0 | Q13: =K13*P13 | S13: =Q13-R13 | U13: =K13*T13 | W13: =U13-V13 | Y13: =K13*X13 | AA13: =Y13-Z13 | AC13: =K13*AB13 | AE13: =AC13-AD13 | AF13: 0 | AG13: =K13*AF13 | AI13: =AG13-AH13 | AJ13: 0 | AK13: =K13*AJ13 | AM13: =AK13-AL13 | AN13: 0 | AO13: =K13*AN13 | AQ13: =AO13-AP13 | AS13: =K13*AR13 | AU13: =AS13-AT13 | AW13: =K13*AV13 | AY13: =AW13-AX13 | BA13: =K13*AZ13 | BC13: =BA13-BB13 | BE13: =K13*BD13 | BG13: =BE13-BF13 | BI13: =K13*BH13 | BK13: =BI13-BJ13 | BM13: =K13*BL13 | BO13: =BM13-BN13 | BP13: =N13+Q13+U13+Y13+AC13+AG13+AK13+AO13+AS13+AW13+BA13+BE13+BI13+BM13 | BQ13: =N13+R13+V13+Z13+AD13+AH13+AL13+AP13+AT13+AX13+BB13+BF13+BJ13+BN13 | BR13: =BP13-BQ13 | BS13: 0.02 | BT13: / | BU13: 1、自营未实际经营；
A14: 17 | B14: KQCY0017 | C14: 餐饮一分部 | D14: CF272 | E14: 苏州工学院南一食堂 | F14: 强责 | G14: 郑虎 | H14: / | I14: 饼铺 | J14: 纪洪强 | K14: =LET(k,D14&"|"&E14&"|"&H14&"|"&I14&"|"&J14,sk,tblRevenueInput[项目代码]&"|"&tblRevenueInput[项目名称]&"|"&tblRevenueInput[分组作业名称]&"|"&tblRevenueInput[分组作业窗口名称]&"|"&tblRevenueInput[签订人],ok,tblRevenueOverride[项目代码]&"|"&tblRevenueOverride[项目名称]&"|"&tblRevenueOverride[分组作业名称]&"|"&tblRevenueOverride[分组作业窗口名称]&"|"&tblRevenueOverride[责任人],ov,IFERROR(XLOOKUP(k,ok,tblRevenueOverride[营业额覆盖],""),""),IF(ov<>"",ov,IFERROR(XLOOKUP(k,sk,tblRevenueInput[全额营业额合计],""),""))) | N14: 1698.59 | O14: 460000 | P14: 0.08 | Q14: =K14*P14 | R14: 444.3624 | S14: =Q14-R14 | T14: 0 | U14: =K14*T14 | W14: =U14-V14 | X14: 0 | Y14: =K14*X14 | AA14: =Y14-Z14 | AB14: 0.065 | AC14: =K14*AB14 | AD14: 361.04445 | AE14: =AC14-AD14 | AF14: 0.02 | AG14: =K14*AF14 | AH14: 111.0906 | AI14: =AG14-AH14 | AJ14: 0.035 | AK14: =K14*AJ14 | AL14: 194.40855 | AM14: =AK14-AL14 | AN14: 0 | AO14: =K14*AN14 | AQ14: =AO14-AP14 | AR14: 0.03 | AS14: =K14*AR14 | AT14: 166.6359 | AU14: =AS14-AT14 | AV14: 0.06 | AW14: =K14*AV14 | AX14: 333.2718 | AY14: =AW14-AX14 | AZ14: 按实 | BA14: =BB14 | BC14: =BA14-BB14 | BD14: 按实 | BE14: =BF14 | BG14: =BE14-BF14 | BH14: 按实 | BI14: =BJ14 | BK14: =BI14-BJ14 | BL14: 按实 | BM14: =BN14 | BO14: =BM14-BN14 | BP14: =N14+Q14+U14+Y14+AC14+AG14+AK14+AO14+AS14+AW14+BA14+BE14+BI14+BM14 | BQ14: =N14+R14+V14+Z14+AD14+AH14+AL14+AP14+AT14+AX14+BB14+BF14+BJ14+BN14 | BR14: =BP14-BQ14 | BS14: / | BT14: / | BU14: 1、甲方捐赠：35万/年，分组作业未分摊，服务费已包含； 2、采购费：1.35万/年，分组作业未分摊，服务费已包含； | BV14: 1、签订期间：2026.2.25-2026.7.19； 2、指标按照全年换算；
A15: 18 | B15: KQCY0018 | C15: 餐饮一分部 | D15: CF272 | E15: 苏州工学院南一食堂 | F15: 强责 | G15: 郑虎 | H15: / | I15: 粥铺 | J15: 贺明 | K15: =LET(k,D15&"|"&E15&"|"&H15&"|"&I15&"|"&J15,sk,tblRevenueInput[项目代码]&"|"&tblRevenueInput[项目名称]&"|"&tblRevenueInput[分组作业名称]&"|"&tblRevenueInput[分组作业窗口名称]&"|"&tblRevenueInput[签订人],ok,tblRevenueOverride[项目代码]&"|"&tblRevenueOverride[项目名称]&"|"&tblRevenueOverride[分组作业名称]&"|"&tblRevenueOverride[分组作业窗口名称]&"|"&tblRevenueOverride[责任人],ov,IFERROR(XLOOKUP(k,ok,tblRevenueOverride[营业额覆盖],""),""),IF(ov<>"",ov,IFERROR(XLOOKUP(k,sk,tblRevenueInput[全额营业额合计],""),""))) | N15: 1698.59 | O15: 384000 | P15: 0.08 | Q15: =K15*P15 | R15: 417.92 | S15: =Q15-R15 | T15: 0 | U15: =K15*T15 | W15: =U15-V15 | X15: 0 | Y15: =K15*X15 | AA15: =Y15-Z15 | AB15: 0.065 | AC15: =K15*AB15 | AD15: 339.56 | AE15: =AC15-AD15 | AF15: 0.02 | AG15: =K15*AF15 | AH15: 104.48 | AI15: =AG15-AH15 | AJ15: 0.035 | AK15: =K15*AJ15 | AL15: 182.84 | AM15: =AK15-AL15 | AN15: 0 | AO15: =K15*AN15 | AQ15: =AO15-AP15 | AR15: 0.03 | AS15: =K15*AR15 | AT15: 156.72 | AU15: =AS15-AT15 | AV15: 0.06 | AW15: =K15*AV15 | AX15: 313.44 | AY15: =AW15-AX15 | AZ15: 按实 | BA15: =BB15 | BC15: =BA15-BB15 | BD15: 按实 | BE15: =BF15 | BG15: =BE15-BF15 | BH15: 按实 | BI15: =BJ15 | BK15: =BI15-BJ15 | BL15: 按实 | BM15: =BN15 | BO15: =BM15-BN15 | BP15: =N15+Q15+U15+Y15+AC15+AG15+AK15+AO15+AS15+AW15+BA15+BE15+BI15+BM15 | BQ15: =N15+R15+V15+Z15+AD15+AH15+AL15+AP15+AT15+AX15+BB15+BF15+BJ15+BN15 | BR15: =BP15-BQ15 | BS15: / | BT15: / | BU15: 1、甲方捐赠：35万/年，分组作业未分摊，服务费已包含； 2、采购费：1.35万/年，分组作业未分摊，服务费已包含； | BV15: 1、签订期间：2026.2.25-2026.7.19； 2、指标按照全年换算；
A16: 19 | B16: KQCY0019 | C16: 餐饮一分部 | D16: CF272 | E16: 苏州工学院南一食堂 | F16: 强责 | G16: 郑虎 | H16: / | I16: 老乡邨 | J16: 刘少军 | K16: =LET(k,D16&"|"&E16&"|"&H16&"|"&I16&"|"&J16,sk,tblRevenueInput[项目代码]&"|"&tblRevenueInput[项目名称]&"|"&tblRevenueInput[分组作业名称]&"|"&tblRevenueInput[分组作业窗口名称]&"|"&tblRevenueInput[签订人],ok,tblRevenueOverride[项目代码]&"|"&tblRevenueOverride[项目名称]&"|"&tblRevenueOverride[分组作业名称]&"|"&tblRevenueOverride[分组作业窗口名称]&"|"&tblRevenueOverride[责任人],ov,IFERROR(XLOOKUP(k,ok,tblRevenueOverride[营业额覆盖],""),""),IF(ov<>"",ov,IFERROR(XLOOKUP(k,sk,tblRevenueInput[全额营业额合计],""),""))) | N16: 1698.59 | O16: 930000 | P16: 0.08 | Q16: =K16*P16 | R16: 766.96 | S16: =Q16-R16 | T16: 0 | U16: =K16*T16 | W16: =U16-V16 | X16: 0 | Y16: =K16*X16 | AA16: =Y16-Z16 | AB16: 0.065 | AC16: =K16*AB16 | AD16: 623.155 | AE16: =AC16-AD16 | AF16: 0.02 | AG16: =K16*AF16 | AH16: 191.74 | AI16: =AG16-AH16 | AJ16: 0.035 | AK16: =K16*AJ16 | AL16: 335.545 | AM16: =AK16-AL16 | AN16: 0 | AO16: =K16*AN16 | AQ16: =AO16-AP16 | AR16: 0.03 | AS16: =K16*AR16 | AT16: 287.61 | AU16: =AS16-AT16 | AV16: 0.06 | AW16: =K16*AV16 | AX16: 575.22 | AY16: =AW16-AX16 | AZ16: 按实 | BA16: =BB16 | BC16: =BA16-BB16 | BD16: 按实 | BE16: =BF16 | BG16: =BE16-BF16 | BH16: 按实 | BI16: =BJ16 | BK16: =BI16-BJ16 | BL16: 按实 | BM16: =BN16 | BO16: =BM16-BN16 | BP16: =N16+Q16+U16+Y16+AC16+AG16+AK16+AO16+AS16+AW16+BA16+BE16+BI16+BM16 | BQ16: =N16+R16+V16+Z16+AD16+AH16+AL16+AP16+AT16+AX16+BB16+BF16+BJ16+BN16 | BR16: =BP16-BQ16 | BS16: / | BT16: / | BU16: 1、甲方捐赠：35万/年，分组作业未分摊，服务费已包含； 2、采购费：1.35万/年，分组作业未分摊，服务费已包含； | BV16: 1、签订期间：2026.2.25-2026.7.19； 2、指标按照全年换算；
A17: 20 | B17: KQCY0020 | C17: 餐饮一分部 | D17: CF272 | E17: 苏州工学院南一食堂 | F17: 强责 | G17: 郑虎 | H17: / | I17: 科桥小厨 | J17: 吴浩 | K17: =LET(k,D17&"|"&E17&"|"&H17&"|"&I17&"|"&J17,sk,tblRevenueInput[项目代码]&"|"&tblRevenueInput[项目名称]&"|"&tblRevenueInput[分组作业名称]&"|"&tblRevenueInput[分组作业窗口名称]&"|"&tblRevenueInput[签订人],ok,tblRevenueOverride[项目代码]&"|"&tblRevenueOverride[项目名称]&"|"&tblRevenueOverride[分组作业名称]&"|"&tblRevenueOverride[分组作业窗口名称]&"|"&tblRevenueOverride[责任人],ov,IFERROR(XLOOKUP(k,ok,tblRevenueOverride[营业额覆盖],""),""),IF(ov<>"",ov,IFERROR(XLOOKUP(k,sk,tblRevenueInput[全额营业额合计],""),""))) | N17: 1698.59 | O17: 1280000 | P17: 0.06 | Q17: =K17*P17 | R17: 3048.72 | S17: =Q17-R17 | T17: 0 | U17: =K17*T17 | W17: =U17-V17 | X17: 0 | Y17: =K17*X17 | AA17: =Y17-Z17 | AB17: 0.055 | AC17: =K17*AB17 | AD17: 2794.66 | AE17: =AC17-AD17 | AF17: 0.02 | AG17: =K17*AF17 | AH17: 1016.24 | AI17: =AG17-AH17 | AJ17: 0.025 | AK17: =K17*AJ17 | AL17: 1270.3 | AM17: =AK17-AL17 | AN17: 0 | AO17: =K17*AN17 | AQ17: =AO17-AP17 | AR17: 0.03 | AS17: =K17*AR17 | AT17: 1524.36 | AU17: =AS17-AT17 | AV17: 0.06 | AW17: =K17*AV17 | AX17: 3048.72 | AY17: =AW17-AX17 | AZ17: 按实 | BA17: =BB17 | BC17: =BA17-BB17 | BD17: 按实 | BE17: =BF17 | BG17: =BE17-BF17 | BH17: 按实 | BI17: =BJ17 | BK17: =BI17-BJ17 | BL17: 按实 | BM17: =BN17 | BO17: =BM17-BN17 | BP17: =N17+Q17+U17+Y17+AC17+AG17+AK17+AO17+AS17+AW17+BA17+BE17+BI17+BM17 | BQ17: =N17+R17+V17+Z17+AD17+AH17+AL17+AP17+AT17+AX17+BB17+BF17+BJ17+BN17 | BR17: =BP17-BQ17 | BS17: / | BT17: / | BU17: 1、甲方捐赠：35万/年，分组作业未分摊，服务费已包含； 2、采购费：1.35万/年，分组作业未分摊，服务费已包含； | BV17: 1、签订期间：2026.2.25-2026.7.19； 2、指标按照全年换算；
A18: 21 | B18: KQCY0021 | C18: 餐饮一分部 | D18: CF272 | E18: 苏州工学院南一食堂 | F18: 强责 | G18: 郑虎 | H18: / | I18: 清汤米线 | J18: 张郁磊 | K18: =LET(k,D18&"|"&E18&"|"&H18&"|"&I18&"|"&J18,sk,tblRevenueInput[项目代码]&"|"&tblRevenueInput[项目名称]&"|"&tblRevenueInput[分组作业名称]&"|"&tblRevenueInput[分组作业窗口名称]&"|"&tblRevenueInput[签订人],ok,tblRevenueOverride[项目代码]&"|"&tblRevenueOverride[项目名称]&"|"&tblRevenueOverride[分组作业名称]&"|"&tblRevenueOverride[分组作业窗口名称]&"|"&tblRevenueOverride[责任人],ov,IFERROR(XLOOKUP(k,ok,tblRevenueOverride[营业额覆盖],""),""),IF(ov<>"",ov,IFERROR(XLOOKUP(k,sk,tblRevenueInput[全额营业额合计],""),""))) | N18: 1698.59 | O18: 264000 | P18: 0.08 | Q18: =K18*P18 | R18: 92.68 | S18: =Q18-R18 | T18: 0 | U18: =K18*T18 | W18: =U18-V18 | X18: 0 | Y18: =K18*X18 | AA18: =Y18-Z18 | AB18: 0.065 | AC18: =K18*AB18 | AD18: 75.3025 | AE18: =AC18-AD18 | AF18: 0.02 | AG18: =K18*AF18 | AH18: 23.17 | AI18: =AG18-AH18 | AJ18: 0.035 | AK18: =K18*AJ18 | AL18: 40.5475 | AM18: =AK18-AL18 | AN18: 0 | AO18: =K18*AN18 | AQ18: =AO18-AP18 | AR18: 0.03 | AS18: =K18*AR18 | AT18: 34.755 | AU18: =AS18-AT18 | AV18: 0.06 | AW18: =K18*AV18 | AX18: 69.51 | AY18: =AW18-AX18 | AZ18: 按实 | BA18: =BB18 | BC18: =BA18-BB18 | BD18: 按实 | BE18: =BF18 | BG18: =BE18-BF18 | BH18: 按实 | BI18: =BJ18 | BK18: =BI18-BJ18 | BL18: 按实 | BM18: =BN18 | BO18: =BM18-BN18 | BP18: =N18+Q18+U18+Y18+AC18+AG18+AK18+AO18+AS18+AW18+BA18+BE18+BI18+BM18 | BQ18: =N18+R18+V18+Z18+AD18+AH18+AL18+AP18+AT18+AX18+BB18+BF18+BJ18+BN18 | BR18: =BP18-BQ18 | BS18: / | BT18: / | BU18: 1、甲方捐赠：35万/年，分组作业未分摊，服务费已包含； 2、采购费：1.35万/年，分组作业未分摊，服务费已包含； | BV18: 1、签订期间：2026.2.25-2026.7.19； 2、指标按照全年换算；
A19: 22 | B19: KQCY0022 | C19: 餐饮一分部 | D19: CF272 | E19: 苏州工学院南一食堂 | F19: 强责 | G19: 郑虎 | H19: / | I19: 黑鸭堡 | J19: 张郁磊 | K19: =LET(k,D19&"|"&E19&"|"&H19&"|"&I19&"|"&J19,sk,tblRevenueInput[项目代码]&"|"&tblRevenueInput[项目名称]&"|"&tblRevenueInput[分组作业名称]&"|"&tblRevenueInput[分组作业窗口名称]&"|"&tblRevenueInput[签订人],ok,tblRevenueOverride[项目代码]&"|"&tblRevenueOverride[项目名称]&"|"&tblRevenueOverride[分组作业名称]&"|"&tblRevenueOverride[分组作业窗口名称]&"|"&tblRevenueOverride[责任人],ov,IFERROR(XLOOKUP(k,ok,tblRevenueOverride[营业额覆盖],""),""),IF(ov<>"",ov,IFERROR(XLOOKUP(k,sk,tblRevenueInput[全额营业额合计],""),""))) | N19: 0 | O19: 290000 | P19: 0.08 | Q19: =K19*P19 | R19: 75.84 | S19: =Q19-R19 | T19: 0 | U19: =K19*T19 | W19: =U19-V19 | X19: 0 | Y19: =K19*X19 | AA19: =Y19-Z19 | AB19: 0.065 | AC19: =K19*AB19 | AD19: 61.62 | AE19: =AC19-AD19 | AF19: 0.02 | AG19: =K19*AF19 | AH19: 18.96 | AI19: =AG19-AH19 | AJ19: 0.035 | AK19: =K19*AJ19 | AL19: 33.18 | AM19: =AK19-AL19 | AN19: 0 | AO19: =K19*AN19 | AQ19: =AO19-AP19 | AR19: 0.03 | AS19: =K19*AR19 | AT19: 28.44 | AU19: =AS19-AT19 | AV19: 0.06 | AW19: =K19*AV19 | AX19: 56.88 | AY19: =AW19-AX19 | AZ19: 按实 | BA19: =BB19 | BC19: =BA19-BB19 | BD19: 按实 | BE19: =BF19 | BG19: =BE19-BF19 | BH19: 按实 | BI19: =BJ19 | BK19: =BI19-BJ19 | BL19: 按实 | BM19: =BN19 | BO19: =BM19-BN19 | BP19: =N19+Q19+U19+Y19+AC19+AG19+AK19+AO19+AS19+AW19+BA19+BE19+BI19+BM19 | BQ19: =N19+R19+V19+Z19+AD19+AH19+AL19+AP19+AT19+AX19+BB19+BF19+BJ19+BN19 | BR19: =BP19-BQ19 | BS19: / | BT19: / | BU19: 1、甲方捐赠：35万/年，分组作业未分摊，服务费已包含； 2、采购费：1.35万/年，分组作业未分摊，服务费已包含； | BV19: 1、签订期间：2026.2.25-2026.7.19； 2、指标按照全年换算；
A20: 23 | B20: KQCY0023 | C20: 餐饮一分部 | D20: CF272 | E20: 苏州工学院南一食堂 | F20: 强责 | G20: 郑虎 | H20: / | I20: 7分甜 | J20: 纪洪强 | K20: =LET(k,D20&"|"&E20&"|"&H20&"|"&I20&"|"&J20,sk,tblRevenueInput[项目代码]&"|"&tblRevenueInput[项目名称]&"|"&tblRevenueInput[分组作业名称]&"|"&tblRevenueInput[分组作业窗口名称]&"|"&tblRevenueInput[签订人],ok,tblRevenueOverride[项目代码]&"|"&tblRevenueOverride[项目名称]&"|"&tblRevenueOverride[分组作业名称]&"|"&tblRevenueOverride[分组作业窗口名称]&"|"&tblRevenueOverride[责任人],ov,IFERROR(XLOOKUP(k,ok,tblRevenueOverride[营业额覆盖],""),""),IF(ov<>"",ov,IFERROR(XLOOKUP(k,sk,tblRevenueInput[全额营业额合计],""),""))) | N20: 1698.59 | O20: 222000 | P20: 0 | Q20: =K20*P20 | R20: 0 | S20: =Q20-R20 | T20: 0 | U20: =K20*T20 | W20: =U20-V20 | X20: 0 | Y20: =K20*X20 | AA20: =Y20-Z20 | AB20: 0 | AC20: =K20*AB20 | AD20: 0 | AE20: =AC20-AD20 | AF20: 0 | AG20: =K20*AF20 | AH20: 0 | AI20: =AG20-AH20 | AJ20: 0 | AK20: =K20*AJ20 | AL20: 0 | AM20: =AK20-AL20 | AN20: 0 | AO20: =K20*AN20 | AQ20: =AO20-AP20 | AR20: 0 | AS20: =K20*AR20 | AT20: 0 | AU20: =AS20-AT20 | AV20: 按实 | AW20: 522.28 | AX20: 522.28 | AY20: =AW20-AX20 | AZ20: 按实 | BA20: =BB20 | BC20: =BA20-BB20 | BD20: 按实 | BE20: =BF20 | BG20: =BE20-BF20 | BH20: 按实 | BI20: =BJ20 | BK20: =BI20-BJ20 | BL20: 按实 | BM20: =BN20 | BO20: =BM20-BN20 | BP20: =N20+Q20+U20+Y20+AC20+AG20+AK20+AO20+AS20+AW20+BA20+BE20+BI20+BM20 | BQ20: =N20+R20+V20+Z20+AD20+AH20+AL20+AP20+AT20+AX20+BB20+BF20+BJ20+BN20 | BR20: =BP20-BQ20 | BS20: / | BT20: / | BU20: 1、甲方捐赠：35万/年，分组作业未分摊，服务费已包含； 2、采购费：1.35万/年，分组作业未分摊，服务费已包含； | BV20: 1、签订期间：2026.2.25-2026.7.19； 2、指标按照全年换算；
A21: 24 | B21: KQCY0024 | C21: 餐饮一分部 | D21: CF272 | E21: 苏州工学院南一食堂 | F21: 强责 | G21: 郑虎 | H21: / | I21: 药膳鸡 | J21: 匡正娟 | K21: =LET(k,D21&"|"&E21&"|"&H21&"|"&I21&"|"&J21,sk,tblRevenueInput[项目代码]&"|"&tblRevenueInput[项目名称]&"|"&tblRevenueInput[分组作业名称]&"|"&tblRevenueInput[分组作业窗口名称]&"|"&tblRevenueInput[签订人],ok,tblRevenueOverride[项目代码]&"|"&tblRevenueOverride[项目名称]&"|"&tblRevenueOverride[分组作业名称]&"|"&tblRevenueOverride[分组作业窗口名称]&"|"&tblRevenueOverride[责任人],ov,IFERROR(XLOOKUP(k,ok,tblRevenueOverride[营业额覆盖],""),""),IF(ov<>"",ov,IFERROR(XLOOKUP(k,sk,tblRevenueInput[全额营业额合计],""),""))) | N21: 1698.59 | O21: 234000 | P21: 房租4万元/学期，3月一次性付款 | Q21: =R21 | R21: 0 | S21: =Q21-R21 | T21: 0 | U21: =K21*T21 | W21: =U21-V21 | X21: 0 | Y21: =K21*X21 | AA21: =Y21-Z21 | AB21: 0 | AC21: =K21*AB21 | AD21: 0 | AE21: =AC21-AD21 | AF21: 0 | AG21: =K21*AF21 | AH21: 0 | AI21: =AG21-AH21 | AJ21: 0 | AK21: =K21*AJ21 | AL21: 0 | AM21: =AK21-AL21 | AN21: 0 | AO21: =K21*AN21 | AQ21: =AO21-AP21 | AR21: 0.025 | AS21: =K21*AR21 | AT21: 342.4 | AU21: =AS21-AT21 | AV21: 0.055 | AW21: =K21*AV21 | AX21: 753.28 | AY21: =AW21-AX21 | AZ21: 按实 | BA21: =BB21 | BC21: =BA21-BB21 | BD21: 按实 | BE21: =BF21 | BG21: =BE21-BF21 | BH21: 按实 | BI21: =BJ21 | BK21: =BI21-BJ21 | BL21: 按实 | BM21: =BN21 | BO21: =BM21-BN21 | BP21: =N21+Q21+U21+Y21+AC21+AG21+AK21+AO21+AS21+AW21+BA21+BE21+BI21+BM21 | BQ21: =N21+R21+V21+Z21+AD21+AH21+AL21+AP21+AT21+AX21+BB21+BF21+BJ21+BN21 | BR21: =BP21-BQ21 | BS21: / | BT21: / | BU21: 1、甲方捐赠：35万/年，分组作业未分摊，服务费已包含； 2、采购费：1.35万/年，分组作业未分摊，服务费已包含； | BV21: 1、签订期间：2026.2.25-2026.7.19； 2、指标按照全年换算；
A22: 25 | B22: KQCY0025 | C22: 餐饮一分部 | D22: CF272 | E22: 苏州工学院南一食堂 | F22: 强责 | G22: 郑虎 | H22: / | I22: 麻辣香锅 | J22: 纪洪强 | K22: =LET(k,D22&"|"&E22&"|"&H22&"|"&I22&"|"&J22,sk,tblRevenueInput[项目代码]&"|"&tblRevenueInput[项目名称]&"|"&tblRevenueInput[分组作业名称]&"|"&tblRevenueInput[分组作业窗口名称]&"|"&tblRevenueInput[签订人],ok,tblRevenueOverride[项目代码]&"|"&tblRevenueOverride[项目名称]&"|"&tblRevenueOverride[分组作业名称]&"|"&tblRevenueOverride[分组作业窗口名称]&"|"&tblRevenueOverride[责任人],ov,IFERROR(XLOOKUP(k,ok,tblRevenueOverride[营业额覆盖],""),""),IF(ov<>"",ov,IFERROR(XLOOKUP(k,sk,tblRevenueInput[全额营业额合计],""),""))) | N22: 1698.59 | O22: 514000 | P22: 0.08 | Q22: =K22*P22 | R22: 1575.776 | S22: =Q22-R22 | T22: 0 | U22: =K22*T22 | W22: =U22-V22 | X22: 0 | Y22: =K22*X22 | AA22: =Y22-Z22 | AB22: 0.065 | AC22: =K22*AB22 | AD22: 1280.318 | AE22: =AC22-AD22 | AF22: 0.02 | AG22: =K22*AF22 | AH22: 393.944 | AI22: =AG22-AH22 | AJ22: 0.035 | AK22: =K22*AJ22 | AL22: 689.402 | AM22: =AK22-AL22 | AN22: 0 | AO22: =K22*AN22 | AQ22: =AO22-AP22 | AR22: 0.03 | AS22: =K22*AR22 | AT22: 590.916 | AU22: =AS22-AT22 | AV22: 0.06 | AW22: =K22*AV22 | AX22: 1181.832 | AY22: =AW22-AX22 | AZ22: 按实 | BA22: =BB22 | BC22: =BA22-BB22 | BD22: 按实 | BE22: =BF22 | BG22: =BE22-BF22 | BH22: 按实 | BI22: =BJ22 | BK22: =BI22-BJ22 | BL22: 按实 | BM22: =BN22 | BO22: =BM22-BN22 | BP22: =N22+Q22+U22+Y22+AC22+AG22+AK22+AO22+AS22+AW22+BA22+BE22+BI22+BM22 | BQ22: =N22+R22+V22+Z22+AD22+AH22+AL22+AP22+AT22+AX22+BB22+BF22+BJ22+BN22 | BR22: =BP22-BQ22 | BS22: / | BT22: / | BU22: 1、甲方捐赠：35万/年，分组作业未分摊，服务费已包含； 2、采购费：1.35万/年，分组作业未分摊，服务费已包含； | BV22: 1、签订期间：2026.2.25-2026.7.19； 2、指标按照全年换算；
A23: 26 | B23: KQCY0026 | C23: 餐饮一分部 | D23: CF272 | E23: 苏州工学院南一食堂 | F23: 强责 | G23: 郑虎 | H23: / | I23: 生煎牛肉汤 | J23: 徐雪晗 | K23: =LET(k,D23&"|"&E23&"|"&H23&"|"&I23&"|"&J23,sk,tblRevenueInput[项目代码]&"|"&tblRevenueInput[项目名称]&"|"&tblRevenueInput[分组作业名称]&"|"&tblRevenueInput[分组作业窗口名称]&"|"&tblRevenueInput[签订人],ok,tblRevenueOverride[项目代码]&"|"&tblRevenueOverride[项目名称]&"|"&tblRevenueOverride[分组作业名称]&"|"&tblRevenueOverride[分组作业窗口名称]&"|"&tblRevenueOverride[责任人],ov,IFERROR(XLOOKUP(k,ok,tblRevenueOverride[营业额覆盖],""),""),IF(ov<>"",ov,IFERROR(XLOOKUP(k,sk,tblRevenueInput[全额营业额合计],""),""))) | N23: 2956.4 | O23: 316000 | P23: 0.08 | Q23: =K23*P23 | R23: 509.56 | S23: =Q23-R23 | T23: 0 | U23: =K23*T23 | W23: =U23-V23 | X23: 0 | Y23: =K23*X23 | AA23: =Y23-Z23 | AB23: 0.065 | AC23: =K23*AB23 | AD23: 414.0175 | AE23: =AC23-AD23 | AF23: 0.02 | AG23: =K23*AF23 | AH23: 127.39 | AI23: =AG23-AH23 | AJ23: 0.035 | AK23: =K23*AJ23 | AL23: 222.9325 | AM23: =AK23-AL23 | AN23: 0 | AO23: =K23*AN23 | AQ23: =AO23-AP23 | AR23: 0.03 | AS23: =K23*AR23 | AT23: 191.085 | AU23: =AS23-AT23 | AV23: 0.06 | AW23: =K23*AV23 | AX23: 382.17 | AY23: =AW23-AX23 | AZ23: 按实 | BA23: =BB23 | BC23: =BA23-BB23 | BD23: 按实 | BE23: =BF23 | BG23: =BE23-BF23 | BH23: 按实 | BI23: =BJ23 | BK23: =BI23-BJ23 | BL23: 按实 | BM23: =BN23 | BO23: =BM23-BN23 | BP23: =N23+Q23+U23+Y23+AC23+AG23+AK23+AO23+AS23+AW23+BA23+BE23+BI23+BM23 | BQ23: =N23+R23+V23+Z23+AD23+AH23+AL23+AP23+AT23+AX23+BB23+BF23+BJ23+BN23 | BR23: =BP23-BQ23 | BS23: / | BT23: / | BU23: 1、甲方捐赠：35万/年，分组作业未分摊，服务费已包含； 2、采购费：1.35万/年，分组作业未分摊，服务费已包含； | BV23: 1、签订期间：2026.2.25-2026.7.19； 2、指标按照全年换算；
A24: 27 | B24: KQCY0027 | C24: 餐饮一分部 | D24: CF272 | E24: 苏州工学院南一食堂 | F24: 强责 | G24: 郑虎 | H24: / | I24: 西式简餐 | J24: 李明发 | K24: =LET(k,D24&"|"&E24&"|"&H24&"|"&I24&"|"&J24,sk,tblRevenueInput[项目代码]&"|"&tblRevenueInput[项目名称]&"|"&tblRevenueInput[分组作业名称]&"|"&tblRevenueInput[分组作业窗口名称]&"|"&tblRevenueInput[签订人],ok,tblRevenueOverride[项目代码]&"|"&tblRevenueOverride[项目名称]&"|"&tblRevenueOverride[分组作业名称]&"|"&tblRevenueOverride[分组作业窗口名称]&"|"&tblRevenueOverride[责任人],ov,IFERROR(XLOOKUP(k,ok,tblRevenueOverride[营业额覆盖],""),""),IF(ov<>"",ov,IFERROR(XLOOKUP(k,sk,tblRevenueInput[全额营业额合计],""),""))) | N24: 1698.59 | O24: 310000 | P24: 0.08 | Q24: =K24*P24 | R24: 445.12 | S24: =Q24-R24 | T24: 0 | U24: =K24*T24 | W24: =U24-V24 | X24: 0 | Y24: =K24*X24 | AA24: =Y24-Z24 | AB24: 0.065 | AC24: =K24*AB24 | AD24: 361.66 | AE24: =AC24-AD24 | AF24: 0.02 | AG24: =K24*AF24 | AH24: 111.28 | AI24: =AG24-AH24 | AJ24: 0.035 | AK24: =K24*AJ24 | AL24: 194.74 | AM24: =AK24-AL24 | AN24: 0 | AO24: =K24*AN24 | AQ24: =AO24-AP24 | AR24: 0.03 | AS24: =K24*AR24 | AT24: 166.92 | AU24: =AS24-AT24 | AV24: 0.06 | AW24: =K24*AV24 | AX24: 333.84 | AY24: =AW24-AX24 | AZ24: 按实 | BA24: =BB24 | BC24: =BA24-BB24 | BD24: 按实 | BE24: =BF24 | BG24: =BE24-BF24 | BH24: 按实 | BI24: =BJ24 | BK24: =BI24-BJ24 | BL24: 按实 | BM24: =BN24 | BO24: =BM24-BN24 | BP24: =N24+Q24+U24+Y24+AC24+AG24+AK24+AO24+AS24+AW24+BA24+BE24+BI24+BM24 | BQ24: =N24+R24+V24+Z24+AD24+AH24+AL24+AP24+AT24+AX24+BB24+BF24+BJ24+BN24 | BR24: =BP24-BQ24 | BS24: / | BT24: / | BU24: 1、甲方捐赠：35万/年，分组作业未分摊，服务费已包含； 2、采购费：1.35万/年，分组作业未分摊，服务费已包含； | BV24: 1、签订期间：2026.2.25-2026.7.19； 2、指标按照全年换算；
A25: 28 | B25: KQCY0028 | C25: 餐饮一分部 | D25: CF272 | E25: 苏州工学院南一食堂 | F25: 强责 | G25: 郑虎 | H25: / | I25: 苏式面 | J25: 许正芳 | K25: =LET(k,D25&"|"&E25&"|"&H25&"|"&I25&"|"&J25,sk,tblRevenueInput[项目代码]&"|"&tblRevenueInput[项目名称]&"|"&tblRevenueInput[分组作业名称]&"|"&tblRevenueInput[分组作业窗口名称]&"|"&tblRevenueInput[签订人],ok,tblRevenueOverride[项目代码]&"|"&tblRevenueOverride[项目名称]&"|"&tblRevenueOverride[分组作业名称]&"|"&tblRevenueOverride[分组作业窗口名称]&"|"&tblRevenueOverride[责任人],ov,IFERROR(XLOOKUP(k,ok,tblRevenueOverride[营业额覆盖],""),""),IF(ov<>"",ov,IFERROR(XLOOKUP(k,sk,tblRevenueInput[全额营业额合计],""),""))) | N25: 28 | O25: 530000 | P25: 0.08 | Q25: =K25*P25 | R25: 769.72 | S25: =Q25-R25 | T25: 0 | U25: =K25*T25 | W25: =U25-V25 | X25: 0 | Y25: =K25*X25 | AA25: =Y25-Z25 | AB25: 0.065 | AC25: =K25*AB25 | AD25: 625.3975 | AE25: =AC25-AD25 | AF25: 0.02 | AG25: =K25*AF25 | AH25: 192.43 | AI25: =AG25-AH25 | AJ25: 0.035 | AK25: =K25*AJ25 | AL25: 336.7525 | AM25: =AK25-AL25 | AN25: 0 | AO25: =K25*AN25 | AQ25: =AO25-AP25 | AR25: 0.03 | AS25: =K25*AR25 | AT25: 288.645 | AU25: =AS25-AT25 | AV25: 0.06 | AW25: =K25*AV25 | AX25: 577.29 | AY25: =AW25-AX25 | AZ25: 按实 | BA25: =BB25 | BC25: =BA25-BB25 | BD25: 按实 | BE25: =BF25 | BG25: =BE25-BF25 | BH25: 按实 | BI25: =BJ25 | BK25: =BI25-BJ25 | BL25: 按实 | BM25: =BN25 | BO25: =BM25-BN25 | BP25: =N25+Q25+U25+Y25+AC25+AG25+AK25+AO25+AS25+AW25+BA25+BE25+BI25+BM25 | BQ25: =N25+R25+V25+Z25+AD25+AH25+AL25+AP25+AT25+AX25+BB25+BF25+BJ25+BN25 | BR25: =BP25-BQ25 | BS25: / | BT25: / | BU25: 1、甲方捐赠：35万/年，分组作业未分摊，服务费已包含； 2、采购费：1.35万/年，分组作业未分摊，服务费已包含； | BV25: 1、签订期间：2026.2.25-2026.7.19； 2、指标按照全年换算；
A26: 29 | B26: KQCY0029 | C26: 餐饮一分部 | D26: CF272 | E26: 苏州工学院南一食堂 | F26: 强责 | G26: 郑虎 | H26: / | I26: 王记炒饭 | J26: 王梓骏 | K26: =LET(k,D26&"|"&E26&"|"&H26&"|"&I26&"|"&J26,sk,tblRevenueInput[项目代码]&"|"&tblRevenueInput[项目名称]&"|"&tblRevenueInput[分组作业名称]&"|"&tblRevenueInput[分组作业窗口名称]&"|"&tblRevenueInput[签订人],ok,tblRevenueOverride[项目代码]&"|"&tblRevenueOverride[项目名称]&"|"&tblRevenueOverride[分组作业名称]&"|"&tblRevenueOverride[分组作业窗口名称]&"|"&tblRevenueOverride[责任人],ov,IFERROR(XLOOKUP(k,ok,tblRevenueOverride[营业额覆盖],""),""),IF(ov<>"",ov,IFERROR(XLOOKUP(k,sk,tblRevenueInput[全额营业额合计],""),""))) | N26: 3397.18 | O26: 526000 | P26: 0.08 | Q26: =K26*P26 | R26: 1282.24 | S26: =Q26-R26 | T26: 0 | U26: =K26*T26 | W26: =U26-V26 | X26: 0 | Y26: =K26*X26 | AA26: =Y26-Z26 | AB26: 0.065 | AC26: =K26*AB26 | AD26: 1041.82 | AE26: =AC26-AD26 | AF26: 0.02 | AG26: =K26*AF26 | AH26: 320.56 | AI26: =AG26-AH26 | AJ26: 0.035 | AK26: =K26*AJ26 | AL26: 560.98 | AM26: =AK26-AL26 | AN26: 0 | AO26: =K26*AN26 | AQ26: =AO26-AP26 | AR26: 0.03 | AS26: =K26*AR26 | AT26: 480.84 | AU26: =AS26-AT26 | AV26: 0.06 | AW26: =K26*AV26 | AX26: 961.68 | AY26: =AW26-AX26 | AZ26: 按实 | BA26: =BB26 | BC26: =BA26-BB26 | BD26: 按实 | BE26: =BF26 | BG26: =BE26-BF26 | BH26: 按实 | BI26: =BJ26 | BK26: =BI26-BJ26 | BL26: 按实 | BM26: =BN26 | BO26: =BM26-BN26 | BP26: =N26+Q26+U26+Y26+AC26+AG26+AK26+AO26+AS26+AW26+BA26+BE26+BI26+BM26 | BQ26: =N26+R26+V26+Z26+AD26+AH26+AL26+AP26+AT26+AX26+BB26+BF26+BJ26+BN26 | BR26: =BP26-BQ26 | BS26: / | BT26: / | BU26: 1、甲方捐赠：35万/年，分组作业未分摊，服务费已包含； 2、采购费：1.35万/年，分组作业未分摊，服务费已包含； | BV26: 1、签订期间：2026.2.25-2026.7.19； 2、指标按照全年换算；
A27: 30 | B27: KQCY0030 | C27: 餐饮一分部 | D27: CF272 | E27: 苏州工学院南一食堂 | F27: 强责 | G27: 郑虎 | H27: / | I27: 烤鸭 | J27: 王鑫 | K27: =LET(k,D27&"|"&E27&"|"&H27&"|"&I27&"|"&J27,sk,tblRevenueInput[项目代码]&"|"&tblRevenueInput[项目名称]&"|"&tblRevenueInput[分组作业名称]&"|"&tblRevenueInput[分组作业窗口名称]&"|"&tblRevenueInput[签订人],ok,tblRevenueOverride[项目代码]&"|"&tblRevenueOverride[项目名称]&"|"&tblRevenueOverride[分组作业名称]&"|"&tblRevenueOverride[分组作业窗口名称]&"|"&tblRevenueOverride[责任人],ov,IFERROR(XLOOKUP(k,ok,tblRevenueOverride[营业额覆盖],""),""),IF(ov<>"",ov,IFERROR(XLOOKUP(k,sk,tblRevenueInput[全额营业额合计],""),""))) | N27: 1698.59 | O27: 530000 | P27: 0.08 | Q27: =K27*P27 | R27: 1305.12 | S27: =Q27-R27 | T27: 0 | U27: =K27*T27 | W27: =U27-V27 | X27: 0 | Y27: =K27*X27 | AA27: =Y27-Z27 | AB27: 0.065 | AC27: =K27*AB27 | AD27: 1060.41 | AE27: =AC27-AD27 | AF27: 0.02 | AG27: =K27*AF27 | AH27: 326.28 | AI27: =AG27-AH27 | AJ27: 0.035 | AK27: =K27*AJ27 | AL27: 570.99 | AM27: =AK27-AL27 | AN27: 0 | AO27: =K27*AN27 | AQ27: =AO27-AP27 | AR27: 0.03 | AS27: =K27*AR27 | AT27: 489.42 | AU27: =AS27-AT27 | AV27: 0.06 | AW27: =K27*AV27 | AX27: 978.84 | AY27: =AW27-AX27 | AZ27: 按实 | BA27: =BB27 | BC27: =BA27-BB27 | BD27: 按实 | BE27: =BF27 | BG27: =BE27-BF27 | BH27: 按实 | BI27: =BJ27 | BK27: =BI27-BJ27 | BL27: 按实 | BM27: =BN27 | BO27: =BM27-BN27 | BP27: =N27+Q27+U27+Y27+AC27+AG27+AK27+AO27+AS27+AW27+BA27+BE27+BI27+BM27 | BQ27: =N27+R27+V27+Z27+AD27+AH27+AL27+AP27+AT27+AX27+BB27+BF27+BJ27+BN27 | BR27: =BP27-BQ27 | BS27: / | BT27: / | BU27: 1、甲方捐赠：35万/年，分组作业未分摊，服务费已包含； 2、采购费：1.35万/年，分组作业未分摊，服务费已包含； | BV27: 1、签订期间：2026.2.25-2026.7.19； 2、指标按照全年换算；
A28: 31 | B28: KQCY0031 | C28: 餐饮一分部 | D28: CF272 | E28: 苏州工学院南一食堂 | F28: 强责 | G28: 郑虎 | H28: / | I28: 小街胡同牛杂面 | J28: 黄雨 | K28: =LET(k,D28&"|"&E28&"|"&H28&"|"&I28&"|"&J28,sk,tblRevenueInput[项目代码]&"|"&tblRevenueInput[项目名称]&"|"&tblRevenueInput[分组作业名称]&"|"&tblRevenueInput[分组作业窗口名称]&"|"&tblRevenueInput[签订人],ok,tblRevenueOverride[项目代码]&"|"&tblRevenueOverride[项目名称]&"|"&tblRevenueOverride[分组作业名称]&"|"&tblRevenueOverride[分组作业窗口名称]&"|"&tblRevenueOverride[责任人],ov,IFERROR(XLOOKUP(k,ok,tblRevenueOverride[营业额覆盖],""),""),IF(ov<>"",ov,IFERROR(XLOOKUP(k,sk,tblRevenueInput[全额营业额合计],""),""))) | N28: 1698.59 | O28: 360000 | P28: 0.08 | Q28: =K28*P28 | R28: 1520.88 | S28: =Q28-R28 | T28: 0 | U28: =K28*T28 | W28: =U28-V28 | X28: 0 | Y28: =K28*X28 | AA28: =Y28-Z28 | AB28: 0.065 | AC28: =K28*AB28 | AD28: 1235.715 | AE28: =AC28-AD28 | AF28: 0.02 | AG28: =K28*AF28 | AH28: 380.22 | AI28: =AG28-AH28 | AJ28: 0.035 | AK28: =K28*AJ28 | AL28: 665.385 | AM28: =AK28-AL28 | AN28: 0 | AO28: =K28*AN28 | AQ28: =AO28-AP28 | AR28: 0.03 | AS28: =K28*AR28 | AT28: 570.33 | AU28: =AS28-AT28 | AV28: 0.06 | AW28: =K28*AV28 | AX28: 1140.66 | AY28: =AW28-AX28 | AZ28: 按实 | BA28: =BB28 | BC28: =BA28-BB28 | BD28: 按实 | BE28: =BF28 | BG28: =BE28-BF28 | BH28: 按实 | BI28: =BJ28 | BK28: =BI28-BJ28 | BL28: 按实 | BM28: =BN28 | BO28: =BM28-BN28 | BP28: =N28+Q28+U28+Y28+AC28+AG28+AK28+AO28+AS28+AW28+BA28+BE28+BI28+BM28 | BQ28: =N28+R28+V28+Z28+AD28+AH28+AL28+AP28+AT28+AX28+BB28+BF28+BJ28+BN28 | BR28: =BP28-BQ28 | BS28: / | BT28: / | BU28: 1、甲方捐赠：35万/年，分组作业未分摊，服务费已包含； 2、采购费：1.35万/年，分组作业未分摊，服务费已包含； | BV28: 1、签订期间：2026.2.25-2026.7.19； 2、指标按照全年换算；
A29: 32 | B29: KQCY0032 | C29: 餐饮一分部 | D29: CF272 | E29: 苏州工学院南一食堂 | F29: 强责 | G29: 郑虎 | H29: / | I29: 汉堡炸鸡 | J29: 陆林峰 | K29: =LET(k,D29&"|"&E29&"|"&H29&"|"&I29&"|"&J29,sk,tblRevenueInput[项目代码]&"|"&tblRevenueInput[项目名称]&"|"&tblRevenueInput[分组作业名称]&"|"&tblRevenueInput[分组作业窗口名称]&"|"&tblRevenueInput[签订人],ok,tblRevenueOverride[项目代码]&"|"&tblRevenueOverride[项目名称]&"|"&tblRevenueOverride[分组作业名称]&"|"&tblRevenueOverride[分组作业窗口名称]&"|"&tblRevenueOverride[责任人],ov,IFERROR(XLOOKUP(k,ok,tblRevenueOverride[营业额覆盖],""),""),IF(ov<>"",ov,IFERROR(XLOOKUP(k,sk,tblRevenueInput[全额营业额合计],""),""))) | N29: 0 | O29: 366000 | P29: 0.08 | Q29: =K29*P29 | R29: 0 | S29: =Q29-R29 | T29: 0 | U29: =K29*T29 | W29: =U29-V29 | X29: 0 | Y29: =K29*X29 | AA29: =Y29-Z29 | AB29: 0.065 | AC29: =K29*AB29 | AD29: 0 | AE29: =AC29-AD29 | AF29: 0.02 | AG29: =K29*AF29 | AH29: 0 | AI29: =AG29-AH29 | AJ29: 0.035 | AK29: =K29*AJ29 | AL29: 0 | AM29: =AK29-AL29 | AN29: 0 | AO29: =K29*AN29 | AQ29: =AO29-AP29 | AR29: 0.03 | AS29: =K29*AR29 | AT29: 0 | AU29: =AS29-AT29 | AV29: 0.06 | AW29: =K29*AV29 | AX29: 0 | AY29: =AW29-AX29 | AZ29: 按实 | BA29: =BB29 | BC29: =BA29-BB29 | BD29: 按实 | BE29: =BF29 | BG29: =BE29-BF29 | BH29: 按实 | BI29: =BJ29 | BK29: =BI29-BJ29 | BL29: 按实 | BM29: =BN29 | BO29: =BM29-BN29 | BP29: =N29+Q29+U29+Y29+AC29+AG29+AK29+AO29+AS29+AW29+BA29+BE29+BI29+BM29 | BQ29: =N29+R29+V29+Z29+AD29+AH29+AL29+AP29+AT29+AX29+BB29+BF29+BJ29+BN29 | BR29: =BP29-BQ29 | BS29: / | BT29: / | BU29: 1、甲方捐赠：35万/年，分组作业未分摊，服务费已包含； 2、采购费：1.35万/年，分组作业未分摊，服务费已包含； | BV29: 1、签订期间：2026.2.25-2026.7.19； 2、指标按照全年换算；
A30: 33 | B30: KQCY0033 | C30: 餐饮一分部 | D30: CF272 | E30: 苏州工学院南一食堂 | F30: 强责 | G30: 郑虎 | H30: / | I30: 旋转小火锅 | J30: 潘祥 | K30: =LET(k,D30&"|"&E30&"|"&H30&"|"&I30&"|"&J30,sk,tblRevenueInput[项目代码]&"|"&tblRevenueInput[项目名称]&"|"&tblRevenueInput[分组作业名称]&"|"&tblRevenueInput[分组作业窗口名称]&"|"&tblRevenueInput[签订人],ok,tblRevenueOverride[项目代码]&"|"&tblRevenueOverride[项目名称]&"|"&tblRevenueOverride[分组作业名称]&"|"&tblRevenueOverride[分组作业窗口名称]&"|"&tblRevenueOverride[责任人],ov,IFERROR(XLOOKUP(k,ok,tblRevenueOverride[营业额覆盖],""),""),IF(ov<>"",ov,IFERROR(XLOOKUP(k,sk,tblRevenueInput[全额营业额合计],""),""))) | N30: 0 | O30: 284000 | P30: 0.06 | Q30: =K30*P30 | R30: 0 | S30: =Q30-R30 | T30: 0 | U30: =K30*T30 | W30: =U30-V30 | X30: 0 | Y30: =K30*X30 | AA30: =Y30-Z30 | AB30: 0.065 | AC30: =K30*AB30 | AD30: 0 | AE30: =AC30-AD30 | AF30: 0.02 | AG30: =K30*AF30 | AH30: 0 | AI30: =AG30-AH30 | AJ30: 0.025 | AK30: =K30*AJ30 | AL30: 0 | AM30: =AK30-AL30 | AN30: 0 | AO30: =K30*AN30 | AQ30: =AO30-AP30 | AR30: 0.03 | AS30: =K30*AR30 | AT30: 0 | AU30: =AS30-AT30 | AV30: 0.06 | AW30: =K30*AV30 | AX30: 0 | AY30: =AW30-AX30 | AZ30: 按实 | BA30: =BB30 | BC30: =BA30-BB30 | BD30: 按实 | BE30: =BF30 | BG30: =BE30-BF30 | BH30: 按实 | BI30: =BJ30 | BK30: =BI30-BJ30 | BL30: 按实 | BM30: 36324 | BN30: 36324 | BO30: =BM30-BN30 | BP30: =N30+Q30+U30+Y30+AC30+AG30+AK30+AO30+AS30+AW30+BA30+BE30+BI30+BM30 | BQ30: =N30+R30+V30+Z30+AD30+AH30+AL30+AP30+AT30+AX30+BB30+BF30+BJ30+BN30 | BR30: =BP30-BQ30 | BS30: / | BT30: / | BU30: 1、甲方捐赠：35万/年，分组作业未分摊，服务费已包含； 2、采购费：1.35万/年，分组作业未分摊，服务费已包含； | BV30: 1、签订期间：2026.2.25-2026.7.19； 2、指标按照全年换算； 3、已撤场（2026年3月）；
A31: 43 | B31: KQCY0043 | C31: 餐饮二分部 | D31: CF125 | E31: 西浦大学宏愿食堂（南） | F31: 分组作业 | G31: 徐敏娟 | H31: / | I31: 麻辣烫 | J31: 何军军 | K31: =LET(k,D31&"|"&E31&"|"&H31&"|"&I31&"|"&J31,sk,tblRevenueInput[项目代码]&"|"&tblRevenueInput[项目名称]&"|"&tblRevenueInput[分组作业名称]&"|"&tblRevenueInput[分组作业窗口名称]&"|"&tblRevenueInput[签订人],ok,tblRevenueOverride[项目代码]&"|"&tblRevenueOverride[项目名称]&"|"&tblRevenueOverride[分组作业名称]&"|"&tblRevenueOverride[分组作业窗口名称]&"|"&tblRevenueOverride[责任人],ov,IFERROR(XLOOKUP(k,ok,tblRevenueOverride[营业额覆盖],""),""),IF(ov<>"",ov,IFERROR(XLOOKUP(k,sk,tblRevenueInput[全额营业额合计],""),""))) | N31: 20433.09 | O31: 850000 | P31: 0.12 | Q31: =K31*P31 | R31: 4953.55 | S31: =Q31-R31 | T31: 按照实际收取 | U31: =V31 | W31: =U31-V31 | X31: 0.02 | Y31: =K31*X31 | Z31: 825 | AA31: =Y31-Z31 | AB31: 0 | AC31: =K31*AB31 | AE31: =AC31-AD31 | AF31: 0 | AG31: =K31*AF31 | AI31: =AG31-AH31 | AJ31: 0 | AK31: =K31*AJ31 | AM31: =AK31-AL31 | AN31: 0 | AO31: =K31*AN31 | AQ31: =AO31-AP31 | AR31: 按照实际收取 | AS31: =AT31 | AT31: 4577 | AU31: =AS31-AT31 | AV31: 按照实际收取 | AW31: =AX31 | AX31: 0 | AY31: =AW31-AX31 | AZ31: 按实 | BA31: =BB31 | BB31: 0 | BC31: =BA31-BB31 | BD31: 0.035 | BE31: =K31*BD31 | BF31: 0 | BG31: =BE31-BF31 | BH31: 0 | BI31: =K31*BH31 | BK31: =BI31-BJ31 | BL31: 按实 | BM31: =BN31 | BN31: 10604.51 | BO31: =BM31-BN31 | BP31: =N31+Q31+U31+Y31+AC31+AG31+AK31+AO31+AS31+AW31+BA31+BE31+BI31+BM31 | BQ31: =N31+R31+V31+Z31+AD31+AH31+AL31+AP31+AT31+AX31+BB31+BF31+BJ31+BN31 | BR31: =BP31-BQ31 | BS31: / | BT31: / | BU31: 1、装修折旧费：项目反馈不收取，包含在服务费中； | BV31: 1、签订期间：2025.9-2026.8； 2、指标按照全年换算；
A32: 44 | B32: KQCY0044 | C32: 餐饮二分部 | D32: CF125 | E32: 西浦大学宏愿食堂（南） | F32: 分组作业 | G32: 徐敏娟 | H32: / | I32: 小炒 | J32: 王成龙 | K32: =LET(k,D32&"|"&E32&"|"&H32&"|"&I32&"|"&J32,sk,tblRevenueInput[项目代码]&"|"&tblRevenueInput[项目名称]&"|"&tblRevenueInput[分组作业名称]&"|"&tblRevenueInput[分组作业窗口名称]&"|"&tblRevenueInput[签订人],ok,tblRevenueOverride[项目代码]&"|"&tblRevenueOverride[项目名称]&"|"&tblRevenueOverride[分组作业名称]&"|"&tblRevenueOverride[分组作业窗口名称]&"|"&tblRevenueOverride[责任人],ov,IFERROR(XLOOKUP(k,ok,tblRevenueOverride[营业额覆盖],""),""),IF(ov<>"",ov,IFERROR(XLOOKUP(k,sk,tblRevenueInput[全额营业额合计],""),""))) | O32: 1500000 | P32: 0.12 | Q32: =K32*P32 | S32: =Q32-R32 | T32: 按照实际收取 | U32: =V32 | W32: =U32-V32 | X32: 0.02 | Y32: =K32*X32 | AA32: =Y32-Z32 | AB32: 0 | AC32: =K32*AB32 | AE32: =AC32-AD32 | AF32: 0 | AG32: =K32*AF32 | AI32: =AG32-AH32 | AJ32: 0 | AK32: =K32*AJ32 | AM32: =AK32-AL32 | AN32: 0 | AO32: =K32*AN32 | AQ32: =AO32-AP32 | AR32: 按照实际收取 | AS32: =AT32 | AU32: =AS32-AT32 | AV32: 按照实际收取 | AW32: =AX32 | AY32: =AW32-AX32 | AZ32: 按实 | BA32: =BB32 | BC32: =BA32-BB32 | BD32: 0.035 | BE32: =K32*BD32 | BG32: =BE32-BF32 | BH32: 0 | BI32: =K32*BH32 | BK32: =BI32-BJ32 | BL32: 按实 | BM32: =BN32 | BO32: =BM32-BN32 | BP32: =N32+Q32+U32+Y32+AC32+AG32+AK32+AO32+AS32+AW32+BA32+BE32+BI32+BM32 | BQ32: =N32+R32+V32+Z32+AD32+AH32+AL32+AP32+AT32+AX32+BB32+BF32+BJ32+BN32 | BR32: =BP32-BQ32 | BS32: / | BT32: / | BU32: 1、装修折旧费：项目反馈不收取，包含在服务费中； | BV32: 1、签订期间：2025.9-2026.8； 2、指标按照全年换算；
A33: 45 | B33: KQCY0045 | C33: 餐饮二分部 | D33: CF125 | E33: 西浦大学宏愿食堂（南） | F33: 分组作业 | G33: 徐敏娟 | H33: / | I33: 枣糕 | J33: 杜松松 | K33: =LET(k,D33&"|"&E33&"|"&H33&"|"&I33&"|"&J33,sk,tblRevenueInput[项目代码]&"|"&tblRevenueInput[项目名称]&"|"&tblRevenueInput[分组作业名称]&"|"&tblRevenueInput[分组作业窗口名称]&"|"&tblRevenueInput[签订人],ok,tblRevenueOverride[项目代码]&"|"&tblRevenueOverride[项目名称]&"|"&tblRevenueOverride[分组作业名称]&"|"&tblRevenueOverride[分组作业窗口名称]&"|"&tblRevenueOverride[责任人],ov,IFERROR(XLOOKUP(k,ok,tblRevenueOverride[营业额覆盖],""),""),IF(ov<>"",ov,IFERROR(XLOOKUP(k,sk,tblRevenueInput[全额营业额合计],""),""))) | O33: 340000 | P33: 0.12 | Q33: =K33*P33 | S33: =Q33-R33 | T33: 按照实际收取 | U33: =V33 | W33: =U33-V33 | X33: 0.02 | Y33: =K33*X33 | AA33: =Y33-Z33 | AB33: 0 | AC33: =K33*AB33 | AE33: =AC33-AD33 | AF33: 0 | AG33: =K33*AF33 | AI33: =AG33-AH33 | AJ33: 0 | AK33: =K33*AJ33 | AM33: =AK33-AL33 | AN33: 0 | AO33: =K33*AN33 | AQ33: =AO33-AP33 | AR33: 按照实际收取 | AS33: =AT33 | AU33: =AS33-AT33 | AV33: 按照实际收取 | AW33: =AX33 | AY33: =AW33-AX33 | AZ33: 按实 | BA33: =BB33 | BC33: =BA33-BB33 | BD33: 0.035 | BE33: =K33*BD33 | BG33: =BE33-BF33 | BH33: 0 | BI33: =K33*BH33 | BK33: =BI33-BJ33 | BL33: 按实 | BM33: =BN33 | BO33: =BM33-BN33 | BP33: =N33+Q33+U33+Y33+AC33+AG33+AK33+AO33+AS33+AW33+BA33+BE33+BI33+BM33 | BQ33: =N33+R33+V33+Z33+AD33+AH33+AL33+AP33+AT33+AX33+BB33+BF33+BJ33+BN33 | BR33: =BP33-BQ33 | BS33: / | BT33: / | BU33: 1、装修折旧费：项目反馈不收取，包含在服务费中； | BV33: 1、签订期间：2025.9-2026.8； 2、指标按照全年换算；
A34: 46 | B34: KQCY0046 | C34: 餐饮二分部 | D34: CF125 | E34: 西浦大学宏愿食堂（南） | F34: 分组作业 | G34: 徐敏娟 | H34: / | I34: 面条 | J34: 葛文静 | K34: =LET(k,D34&"|"&E34&"|"&H34&"|"&I34&"|"&J34,sk,tblRevenueInput[项目代码]&"|"&tblRevenueInput[项目名称]&"|"&tblRevenueInput[分组作业名称]&"|"&tblRevenueInput[分组作业窗口名称]&"|"&tblRevenueInput[签订人],ok,tblRevenueOverride[项目代码]&"|"&tblRevenueOverride[项目名称]&"|"&tblRevenueOverride[分组作业名称]&"|"&tblRevenueOverride[分组作业窗口名称]&"|"&tblRevenueOverride[责任人],ov,IFERROR(XLOOKUP(k,ok,tblRevenueOverride[营业额覆盖],""),""),IF(ov<>"",ov,IFERROR(XLOOKUP(k,sk,tblRevenueInput[全额营业额合计],""),""))) | O34: 365000 | P34: 0.12 | Q34: =K34*P34 | S34: =Q34-R34 | T34: 按照实际收取 | U34: =V34 | W34: =U34-V34 | X34: 0.02 | Y34: =K34*X34 | AA34: =Y34-Z34 | AB34: 0 | AC34: =K34*AB34 | AE34: =AC34-AD34 | AF34: 0 | AG34: =K34*AF34 | AI34: =AG34-AH34 | AJ34: 0 | AK34: =K34*AJ34 | AM34: =AK34-AL34 | AN34: 0 | AO34: =K34*AN34 | AQ34: =AO34-AP34 | AR34: 按照实际收取 | AS34: =AT34 | AU34: =AS34-AT34 | AV34: 按照实际收取 | AW34: =AX34 | AY34: =AW34-AX34 | AZ34: 按实 | BA34: =BB34 | BC34: =BA34-BB34 | BD34: 0.035 | BE34: =K34*BD34 | BG34: =BE34-BF34 | BH34: 0 | BI34: =K34*BH34 | BK34: =BI34-BJ34 | BL34: 按实 | BM34: =BN34 | BO34: =BM34-BN34 | BP34: =N34+Q34+U34+Y34+AC34+AG34+AK34+AO34+AS34+AW34+BA34+BE34+BI34+BM34 | BQ34: =N34+R34+V34+Z34+AD34+AH34+AL34+AP34+AT34+AX34+BB34+BF34+BJ34+BN34 | BR34: =BP34-BQ34 | BS34: / | BT34: / | BU34: 1、装修折旧费：项目反馈不收取，包含在服务费中； | BV34: 1、签订期间：2025.9-2026.8； 2、指标按照全年换算；
A35: 47 | B35: KQCY0047 | C35: 餐饮二分部 | D35: CF125 | E35: 西浦大学宏愿食堂（南） | F35: 分组作业 | G35: 徐敏娟 | H35: / | I35: 烤肉 | J35: 杜松松 | K35: =LET(k,D35&"|"&E35&"|"&H35&"|"&I35&"|"&J35,sk,tblRevenueInput[项目代码]&"|"&tblRevenueInput[项目名称]&"|"&tblRevenueInput[分组作业名称]&"|"&tblRevenueInput[分组作业窗口名称]&"|"&tblRevenueInput[签订人],ok,tblRevenueOverride[项目代码]&"|"&tblRevenueOverride[项目名称]&"|"&tblRevenueOverride[分组作业名称]&"|"&tblRevenueOverride[分组作业窗口名称]&"|"&tblRevenueOverride[责任人],ov,IFERROR(XLOOKUP(k,ok,tblRevenueOverride[营业额覆盖],""),""),IF(ov<>"",ov,IFERROR(XLOOKUP(k,sk,tblRevenueInput[全额营业额合计],""),""))) | O35: 370000 | P35: 0.12 | Q35: =K35*P35 | S35: =Q35-R35 | T35: 按照实际收取 | U35: =V35 | W35: =U35-V35 | X35: 0.02 | Y35: =K35*X35 | AA35: =Y35-Z35 | AB35: 0 | AC35: =K35*AB35 | AE35: =AC35-AD35 | AF35: 0 | AG35: =K35*AF35 | AI35: =AG35-AH35 | AJ35: 0 | AK35: =K35*AJ35 | AM35: =AK35-AL35 | AN35: 0 | AO35: =K35*AN35 | AQ35: =AO35-AP35 | AR35: 按照实际收取 | AS35: =AT35 | AU35: =AS35-AT35 | AV35: 按照实际收取 | AW35: =AX35 | AY35: =AW35-AX35 | AZ35: 按实 | BA35: =BB35 | BC35: =BA35-BB35 | BD35: 0.035 | BE35: =K35*BD35 | BG35: =BE35-BF35 | BH35: 0 | BI35: =K35*BH35 | BK35: =BI35-BJ35 | BL35: 按实 | BM35: =BN35 | BO35: =BM35-BN35 | BP35: =N35+Q35+U35+Y35+AC35+AG35+AK35+AO35+AS35+AW35+BA35+BE35+BI35+BM35 | BQ35: =N35+R35+V35+Z35+AD35+AH35+AL35+AP35+AT35+AX35+BB35+BF35+BJ35+BN35 | BR35: =BP35-BQ35 | BS35: / | BT35: / | BU35: 1、装修折旧费：项目反馈不收取，包含在服务费中； | BV35: 1、签订期间：2025.9-2026.8； 2、指标按照全年换算；
A36: 48 | B36: KQCY0048 | C36: 餐饮二分部 | D36: CF125 | E36: 西浦大学宏愿食堂（南） | F36: 分组作业 | G36: 徐敏娟 | H36: / | I36: 粉丝汤 | J36: 李鑫 | K36: =LET(k,D36&"|"&E36&"|"&H36&"|"&I36&"|"&J36,sk,tblRevenueInput[项目代码]&"|"&tblRevenueInput[项目名称]&"|"&tblRevenueInput[分组作业名称]&"|"&tblRevenueInput[分组作业窗口名称]&"|"&tblRevenueInput[签订人],ok,tblRevenueOverride[项目代码]&"|"&tblRevenueOverride[项目名称]&"|"&tblRevenueOverride[分组作业名称]&"|"&tblRevenueOverride[分组作业窗口名称]&"|"&tblRevenueOverride[责任人],ov,IFERROR(XLOOKUP(k,ok,tblRevenueOverride[营业额覆盖],""),""),IF(ov<>"",ov,IFERROR(XLOOKUP(k,sk,tblRevenueInput[全额营业额合计],""),""))) | O36: 440000 | P36: 0.12 | Q36: =K36*P36 | S36: =Q36-R36 | T36: 按照实际收取 | U36: =V36 | W36: =U36-V36 | X36: 0.02 | Y36: =K36*X36 | AA36: =Y36-Z36 | AB36: 0 | AC36: =K36*AB36 | AE36: =AC36-AD36 | AF36: 0 | AG36: =K36*AF36 | AI36: =AG36-AH36 | AJ36: 0 | AK36: =K36*AJ36 | AM36: =AK36-AL36 | AN36: 0 | AO36: =K36*AN36 | AQ36: =AO36-AP36 | AR36: 按照实际收取 | AS36: =AT36 | AU36: =AS36-AT36 | AV36: 按照实际收取 | AW36: =AX36 | AY36: =AW36-AX36 | AZ36: 按实 | BA36: =BB36 | BC36: =BA36-BB36 | BD36: 0.035 | BE36: =K36*BD36 | BG36: =BE36-BF36 | BH36: 0 | BI36: =K36*BH36 | BK36: =BI36-BJ36 | BL36: 按实 | BM36: =BN36 | BO36: =BM36-BN36 | BP36: =N36+Q36+U36+Y36+AC36+AG36+AK36+AO36+AS36+AW36+BA36+BE36+BI36+BM36 | BQ36: =N36+R36+V36+Z36+AD36+AH36+AL36+AP36+AT36+AX36+BB36+BF36+BJ36+BN36 | BR36: =BP36-BQ36 | BS36: / | BT36: / | BU36: 1、装修折旧费：项目反馈不收取，包含在服务费中； | BV36: 1、签订期间：2025.9-2026.8； 2、指标按照全年换算；
A37: 50 | B37: KQCY0050 | C37: 餐饮二分部 | D37: CF137 | E37: 西浦大学宏愿食堂（北） | F37: 分组作业 | G37: 徐敏娟 | H37: / | I37: 滑蛋饭 | J37: 赵广伟 | K37: =LET(k,D37&"|"&E37&"|"&H37&"|"&I37&"|"&J37,sk,tblRevenueInput[项目代码]&"|"&tblRevenueInput[项目名称]&"|"&tblRevenueInput[分组作业名称]&"|"&tblRevenueInput[分组作业窗口名称]&"|"&tblRevenueInput[签订人],ok,tblRevenueOverride[项目代码]&"|"&tblRevenueOverride[项目名称]&"|"&tblRevenueOverride[分组作业名称]&"|"&tblRevenueOverride[分组作业窗口名称]&"|"&tblRevenueOverride[责任人],ov,IFERROR(XLOOKUP(k,ok,tblRevenueOverride[营业额覆盖],""),""),IF(ov<>"",ov,IFERROR(XLOOKUP(k,sk,tblRevenueInput[全额营业额合计],""),""))) | N37: 13454.15 | O37: 345000 | P37: 0.14 | Q37: =K37*P37 | R37: 0 | S37: =Q37-R37 | T37: 0 | U37: =K37*T37 | W37: =U37-V37 | X37: 0.02 | Y37: =K37*X37 | Z37: 0 | AA37: =Y37-Z37 | AB37: 0 | AC37: =K37*AB37 | AE37: =AC37-AD37 | AF37: 0 | AG37: =K37*AF37 | AI37: =AG37-AH37 | AJ37: 0 | AK37: =K37*AJ37 | AM37: =AK37-AL37 | AN37: 0 | AO37: =K37*AN37 | AQ37: =AO37-AP37 | AR37: 0.05 | AS37: =K37*AR37 | AT37: 0 | AU37: =AS37-AT37 | AV37: 0.06 | AW37: =K37*AV37 | AX37: 0 | AY37: =AW37-AX37 | AZ37: 0.01 | BA37: =K37*AZ37 | BB37: 0 | BC37: =BA37-BB37 | BD37: 0 | BE37: =K37*BD37 | BG37: =BE37-BF37 | BH37: 0 | BI37: =K37*BH37 | BK37: =BI37-BJ37 | BL37: 按实 | BM37: =BN37 | BN37: 0 | BO37: =BM37-BN37 | BP37: =N37+Q37+U37+Y37+AC37+AG37+AK37+AO37+AS37+AW37+BA37+BE37+BI37+BM37 | BQ37: =N37+R37+V37+Z37+AD37+AH37+AL37+AP37+AT37+AX37+BB37+BF37+BJ37+BN37 | BR37: =BP37-BQ37 | BS37: / | BT37: / | BU37: 1、装修折旧费：项目反馈不收取，包含在服务费中； 2、甲方房租：项目反馈不收取，包含在服务费中； | BV37: 1、签订期间：2025.10-2026.9； 2、指标按照全年换算；
A38: 51 | B38: KQCY0051 | C38: 餐饮二分部 | D38: CF137 | E38: 西浦大学宏愿食堂（北） | F38: 分组作业 | G38: 徐敏娟 | H38: / | I38: 手工水饺 | J38: 赵玉才 | K38: =LET(k,D38&"|"&E38&"|"&H38&"|"&I38&"|"&J38,sk,tblRevenueInput[项目代码]&"|"&tblRevenueInput[项目名称]&"|"&tblRevenueInput[分组作业名称]&"|"&tblRevenueInput[分组作业窗口名称]&"|"&tblRevenueInput[签订人],ok,tblRevenueOverride[项目代码]&"|"&tblRevenueOverride[项目名称]&"|"&tblRevenueOverride[分组作业名称]&"|"&tblRevenueOverride[分组作业窗口名称]&"|"&tblRevenueOverride[责任人],ov,IFERROR(XLOOKUP(k,ok,tblRevenueOverride[营业额覆盖],""),""),IF(ov<>"",ov,IFERROR(XLOOKUP(k,sk,tblRevenueInput[全额营业额合计],""),""))) | O38: 475000 | P38: 0.14 | Q38: =K38*P38 | S38: =Q38-R38 | T38: 0 | U38: =K38*T38 | W38: =U38-V38 | X38: 0.02 | Y38: =K38*X38 | AA38: =Y38-Z38 | AB38: 0 | AC38: =K38*AB38 | AE38: =AC38-AD38 | AF38: 0 | AG38: =K38*AF38 | AI38: =AG38-AH38 | AJ38: 0 | AK38: =K38*AJ38 | AM38: =AK38-AL38 | AN38: 0 | AO38: =K38*AN38 | AQ38: =AO38-AP38 | AR38: 0.05 | AS38: =K38*AR38 | AU38: =AS38-AT38 | AV38: 0.06 | AW38: =K38*AV38 | AY38: =AW38-AX38 | AZ38: 0.01 | BA38: =K38*AZ38 | BC38: =BA38-BB38 | BD38: 0 | BE38: =K38*BD38 | BG38: =BE38-BF38 | BH38: 0 | BI38: =K38*BH38 | BK38: =BI38-BJ38 | BL38: 按实 | BM38: =BN38 | BO38: =BM38-BN38 | BP38: =N38+Q38+U38+Y38+AC38+AG38+AK38+AO38+AS38+AW38+BA38+BE38+BI38+BM38 | BQ38: =N38+R38+V38+Z38+AD38+AH38+AL38+AP38+AT38+AX38+BB38+BF38+BJ38+BN38 | BR38: =BP38-BQ38 | BS38: / | BT38: / | BU38: 1、装修折旧费：项目反馈不收取，包含在服务费中； 2、甲方房租：项目反馈不收取，包含在服务费中； | BV38: 1、签订期间：2025.10-2026.9； 2、指标按照全年换算；
A39: 52 | B39: KQCY0052 | C39: 餐饮二分部 | D39: CF137 | E39: 西浦大学宏愿食堂（北） | F39: 分组作业 | G39: 徐敏娟 | H39: / | I39: 烤盘饭 | J39: 付昌杰 | K39: =LET(k,D39&"|"&E39&"|"&H39&"|"&I39&"|"&J39,sk,tblRevenueInput[项目代码]&"|"&tblRevenueInput[项目名称]&"|"&tblRevenueInput[分组作业名称]&"|"&tblRevenueInput[分组作业窗口名称]&"|"&tblRevenueInput[签订人],ok,tblRevenueOverride[项目代码]&"|"&tblRevenueOverride[项目名称]&"|"&tblRevenueOverride[分组作业名称]&"|"&tblRevenueOverride[分组作业窗口名称]&"|"&tblRevenueOverride[责任人],ov,IFERROR(XLOOKUP(k,ok,tblRevenueOverride[营业额覆盖],""),""),IF(ov<>"",ov,IFERROR(XLOOKUP(k,sk,tblRevenueInput[全额营业额合计],""),""))) | O39: 875000 | P39: 0.14 | Q39: =K39*P39 | S39: =Q39-R39 | T39: 0 | U39: =K39*T39 | W39: =U39-V39 | X39: 0.02 | Y39: =K39*X39 | AA39: =Y39-Z39 | AB39: 0 | AC39: =K39*AB39 | AE39: =AC39-AD39 | AF39: 0 | AG39: =K39*AF39 | AI39: =AG39-AH39 | AJ39: 0 | AK39: =K39*AJ39 | AM39: =AK39-AL39 | AN39: 0 | AO39: =K39*AN39 | AQ39: =AO39-AP39 | AR39: 0.05 | AS39: =K39*AR39 | AU39: =AS39-AT39 | AV39: 0.06 | AW39: =K39*AV39 | AY39: =AW39-AX39 | AZ39: 0.01 | BA39: =K39*AZ39 | BC39: =BA39-BB39 | BD39: 0 | BE39: =K39*BD39 | BG39: =BE39-BF39 | BH39: 0 | BI39: =K39*BH39 | BK39: =BI39-BJ39 | BL39: 按实 | BM39: =BN39 | BO39: =BM39-BN39 | BP39: =N39+Q39+U39+Y39+AC39+AG39+AK39+AO39+AS39+AW39+BA39+BE39+BI39+BM39 | BQ39: =N39+R39+V39+Z39+AD39+AH39+AL39+AP39+AT39+AX39+BB39+BF39+BJ39+BN39 | BR39: =BP39-BQ39 | BS39: / | BT39: / | BU39: 1、装修折旧费：项目反馈不收取，包含在服务费中； 2、甲方房租：项目反馈不收取，包含在服务费中； | BV39: 1、签订期间：2025.10-2026.9； 2、指标按照全年换算；
A40: 53 | B40: KQCY0053 | C40: 餐饮二分部 | D40: CF137 | E40: 西浦大学宏愿食堂（北） | F40: 分组作业 | G40: 徐敏娟 | H40: / | I40: 大花米线 | J40: 钱卫军 | K40: =LET(k,D40&"|"&E40&"|"&H40&"|"&I40&"|"&J40,sk,tblRevenueInput[项目代码]&"|"&tblRevenueInput[项目名称]&"|"&tblRevenueInput[分组作业名称]&"|"&tblRevenueInput[分组作业窗口名称]&"|"&tblRevenueInput[签订人],ok,tblRevenueOverride[项目代码]&"|"&tblRevenueOverride[项目名称]&"|"&tblRevenueOverride[分组作业名称]&"|"&tblRevenueOverride[分组作业窗口名称]&"|"&tblRevenueOverride[责任人],ov,IFERROR(XLOOKUP(k,ok,tblRevenueOverride[营业额覆盖],""),""),IF(ov<>"",ov,IFERROR(XLOOKUP(k,sk,tblRevenueInput[全额营业额合计],""),""))) | O40: 485000 | P40: 0.14 | Q40: =K40*P40 | S40: =Q40-R40 | T40: 0 | U40: =K40*T40 | W40: =U40-V40 | X40: 0.02 | Y40: =K40*X40 | AA40: =Y40-Z40 | AB40: 0 | AC40: =K40*AB40 | AE40: =AC40-AD40 | AF40: 0 | AG40: =K40*AF40 | AI40: =AG40-AH40 | AJ40: 0 | AK40: =K40*AJ40 | AM40: =AK40-AL40 | AN40: 0 | AO40: =K40*AN40 | AQ40: =AO40-AP40 | AR40: 0.05 | AS40: =K40*AR40 | AU40: =AS40-AT40 | AV40: 0.06 | AW40: =K40*AV40 | AY40: =AW40-AX40 | AZ40: 0.01 | BA40: =K40*AZ40 | BC40: =BA40-BB40 | BD40: 0 | BE40: =K40*BD40 | BG40: =BE40-BF40 | BH40: 0 | BI40: =K40*BH40 | BK40: =BI40-BJ40 | BL40: 按实 | BM40: =BN40 | BO40: =BM40-BN40 | BP40: =N40+Q40+U40+Y40+AC40+AG40+AK40+AO40+AS40+AW40+BA40+BE40+BI40+BM40 | BQ40: =N40+R40+V40+Z40+AD40+AH40+AL40+AP40+AT40+AX40+BB40+BF40+BJ40+BN40 | BR40: =BP40-BQ40 | BS40: / | BT40: / | BU40: 1、装修折旧费：项目反馈不收取，包含在服务费中； 2、甲方房租：项目反馈不收取，包含在服务费中； | BV40: 1、签订期间：2025.10-2026.9； 2、指标按照全年换算；
...

Sheet 营业额数据源
A1: 营业额数据源（每月覆盖粘贴 A:M 数据区）
A2: 数据行从第 4 行开始；目标输出以项目代码、项目名称、班组、窗口、责任人五项进行精确匹配。
A3: 序号 | B3: 档口唯一标志 | C3: 分部名称 | D3: 项目代码 | E3: 项目名称 | F3: 项目类型 | G3: 分组作业名称 | H3: 分组作业窗口名称 | I3: 签订人 | J3: 全额营业额合计 | K3: 备注状态 | L3: 收入会计 | M3: 补充说明
A4: 1 | B4: KQCY0001 | C4: 餐饮一分部 | D4: CF139 | E4: 苏州中科新药篮餐厅 | F4: 自营 | G4: 自营 | H4: / | I4: / | J4: 201107.98 | L4: 谢苗苗 | M4: 已核对
A5: 2 | B5: KQCY0002 | C5: 餐饮一分部 | D5: CF481 | E5: 常熟世华高级中学食堂 | F5: 自营 | G5: 自营 | H5: / | I5: 杨志军 | J5: 66255.63 | L5: 谢苗苗 | M5: 已核对
A6: 3 | B6: KQCY0003 | C6: 餐饮一分部 | D6: CF478 | E6: 苏州华杨电子餐厅 | F6: 强责 | G6: / | H6: / | I6: 武良军 | J6: 170171.4 | L6: 谢苗苗 | M6: 已核对
A7: 4 | B7: KQCY0004 | C7: 餐饮一分部 | D7: CF751 | E7: 国防科大（长沙）食堂 | F7: 人员服务外包 | G7: / | H7: / | I7: / | J7: 621582.5 | L7: 位军浩
A8: 5 | B8: KQCY0005 | C8: 餐饮一分部 | D8: CF474 | E8: 安工大七食堂 | F8: 强责 | G8: / | H8: / | I8: 李俊彦 | J8: 29505.2 | L8: 位军浩
