Workbook

Sheet 汇总表
B1: 科桥餐饮公司应收账款统计表 金额：元
A2: 序号 | B2: 应收账款年度 | C2: 总金额 （截止至2026.5.31） | D2: （1）正常应收帐款 | E2: （2）逾期应收帐款 | K2: 备注
E3: 逾期1个月 | F3: 逾期2-3个月 | G3: 逾期3个月以上-6个月以内（含6个月） | H3: 逾期6个月以上-12个月以内（含12个月） | I3: 逾期12个月以上 | J3: 小计
A4: 1 | B4: 2023年度 | C4: ='2023年度'!G7 -> 2484096 | D4: ='2023年度'!H7 -> 0 | E4: ='2023年度'!I7 -> 0 | F4: ='2023年度'!K7 -> 0 | G4: ='2023年度'!M7 -> 0 | H4: ='2023年度'!O7 -> 0 | I4: ='2023年度'!Q7 -> 2484096 | J4: =SUM(E4:I4) -> 2484096 | K4: （1）正常金额：指1个月以内 （2）异常金额：见附表
A5: 2 | B5: 2024年度 | C5: ='2024年度'!G11 -> 1012801.2 | D5: ='2024年度'!H11 -> 0 | E5: ='2024年度'!I11 -> 0 | F5: ='2024年度'!K11 -> 0 | G5: ='2024年度'!M11 -> 0 | H5: ='2024年度'!O11 -> 0 | I5: ='2024年度'!Q11 -> 1012801.2 | J5: =SUM(E5:I5) -> 1012801.2
A6: 3 | B6: 2025年度 | C6: ='2025年度'!G28 -> 9250486 | D6: ='2025年度'!H28 -> 0 | E6: ='2025年度'!I28 -> 0 | F6: ='2025年度'!K28 -> 0 | G6: ='2025年度'!M28 -> 1857936.8 | H6: ='2025年度'!O28 -> 7391549.2 | I6: ='2025年度'!Q28 -> 1000 | J6: =SUM(E6:I6) -> 9250486
A7: 4 | B7: 2026年1-8月 | C7: ='2026年8月科桥餐饮公司应收账款统计表'!G74 -> 49648334 | D7: ='2026年8月科桥餐饮公司应收账款统计表'!H74 -> 30353932 | E7: ='2026年8月科桥餐饮公司应收账款统计表'!I74 -> 9024761 | F7: ='2026年8月科桥餐饮公司应收账款统计表'!K74 -> 6997639.7 | G7: ='2026年8月科桥餐饮公司应收账款统计表'!M74 -> 3272001 | H7: ='2026年8月科桥餐饮公司应收账款统计表'!O74 -> 0 | I7: ='2026年8月科桥餐饮公司应收账款统计表'!Q74 -> 0 | J7: =SUM(E7:I7) -> 19294402
A8: 总计 | C8: =SUM(C4:C7) -> 62395717 | D8: =SUM(D4:D7) -> 30353932 | E8: =SUM(E4:E7) -> 9024761 | F8: =SUM(F4:F7) -> 6997639.7 | G8: =SUM(G4:G7) -> 5129937.8 | H8: =SUM(H4:H7) -> 7391549.2 | I8: =SUM(I4:I7) -> 3497897.1 | J8: =SUM(J4:J7) -> 32041785
J10: 填报：财务部（收入核算科）
J11: 复核：谢苗苗
J12: 日期：2026/9/4

Sheet 2023年度
A1: 2023年度科桥餐饮公司应收账款统计表 （时间：截至2026.8.31） 金额：元 | B1: 餐饮公司应收账款统计表 | C1: 餐饮公司应收账款统计表 | D1: 餐饮公司应收账款统计表 | E1: 餐饮公司应收账款统计表 | F1: 餐饮公司应收账款统计表 | G1: 餐饮公司应收账款统计表 | H1: 餐饮公司应收账款统计表 | I1: 餐饮公司应收账款统计表 | J1: 餐饮公司应收账款统计表 | K1: 餐饮公司应收账款统计表 | L1: 餐饮公司应收账款统计表 | M1: 餐饮公司应收账款统计表 | N1: 餐饮公司应收账款统计表 | O1: 餐饮公司应收账款统计表 | P1: 餐饮公司应收账款统计表 | Q1: 餐饮公司应收账款统计表 | R1: 餐饮公司应收账款统计表 | S1: 餐饮公司应收账款统计表 | T1: 餐饮公司应收账款统计表
A2: 分部经理 | B2: 分部 | C2: 会计责任人 | D2: 项目编码 | E2: 项目名称 | F2: 合同结算周期（月付、双月付或季付、半年付、年付、一次性等）（考核金合同结束一次性结算、考核金次月结算等） | G2: 应收金额 合计（1）+（2） | H2: （1）正常应收账款 | I2: （2）逾期应收账款 | J2: （2）逾期应收账款 | K2: （2）逾期应收账款 | L2: （2）逾期应收账款 | M2: （2）逾期应收账款 | N2: （2）逾期应收账款 | O2: （2）逾期应收账款 | P2: （2）逾期应收账款 | Q2: （2）逾期应收账款 | R2: （2）逾期应收账款 | S2: （2）逾期应收账款 | T2: （2）逾期应收账款
I3: A.逾期1个月 | J3: 服务费所属期 | K3: B.逾期2-3个月 | L3: 服务费所属期 | M3: C.逾期3个月以上-6个月以内（含6个月） | N3: 服务费所属期 | O3: D.逾期6个月以上-12个月以内（含12个月） | P3: 服务费所属期 | Q3: E.逾期12个月以上 | R3: 服务费所属期 | S3: 小计 | T3: 备注（撤场、合同未签订等）
A4: 丁吟春 | B4: 餐饮二分部 | C4: 位军浩 | D4: CF173 | E4: 高新区一中食堂（汾湖路校区） | F4: 月结、学期 | G4: 1245294.8 | H4: 0 | I4: 0 | K4: 0 | M4: 0 | O4: 0 | Q4: 1245294.8 | R4: 2023-08,2023-09,2023-10,2023-11,2023-12 | S4: 1245294.8
D5: CF179 | E5: 高新区一中食堂（科技城校区） | F5: 月结、学期 | G5: 1224543.1 | H5: 0 | I5: 0 | K5: 0 | M5: 0 | O5: 0 | Q5: 1224543.1 | R5: 2023-08,2023-09,2023-10,2023-11,2023-12 | S5: 1224543.1
D6: CF180 | E6: 高新区一初中食堂（珠江路校区） | F6: 月结、学期 | G6: 14258 | H6: 0 | I6: 0 | K6: 0 | M6: 0 | O6: 0 | Q6: 14258 | R6: 2023-11 | S6: 14258
E7: 部门小计 | G7: =SUM(G4:G6) -> 2484096 | H7: 0 | I7: 0 | K7: 0 | M7: 0 | O7: 0 | Q7: 2484096 | S7: 2484096
A8: 2023年餐饮总、分、子公司等合计 | G8: =G7 -> 2484096 | H8: 0 | I8: 0 | K8: 0 | M8: 0 | O8: 0 | Q8: =Q7 -> 2484096 | S8: =S7 -> 2484096
S11: 填报：财务部（收入核算科）
S12: 复核：谢苗苗
S13: =汇总表!J12 -> 日期：2026/9/4

Sheet 2024年度
A1: 2024年度科桥餐饮公司应收账款统计表 （时间：截至2026.8.31） 金额：元 | B1: 餐饮公司应收账款统计表 | C1: 餐饮公司应收账款统计表 | D1: 餐饮公司应收账款统计表 | E1: 餐饮公司应收账款统计表 | F1: 餐饮公司应收账款统计表 | G1: 餐饮公司应收账款统计表 | H1: 餐饮公司应收账款统计表 | I1: 餐饮公司应收账款统计表 | J1: 餐饮公司应收账款统计表 | K1: 餐饮公司应收账款统计表 | L1: 餐饮公司应收账款统计表 | M1: 餐饮公司应收账款统计表 | N1: 餐饮公司应收账款统计表 | O1: 餐饮公司应收账款统计表 | P1: 餐饮公司应收账款统计表 | Q1: 餐饮公司应收账款统计表 | R1: 餐饮公司应收账款统计表 | S1: 餐饮公司应收账款统计表 | T1: 餐饮公司应收账款统计表
A2: 分部经理 | B2: 分部 | C2: 会计责任人 | D2: 项目编码 | E2: 项目名称 | F2: 合同结算周期（月付、双月付或季付、半年付、年付、一次性等）（考核金合同结束一次性结算、考核金次月结算等） | G2: 应收金额 合计（1）+（2） | H2: （1）正常应收账款 | I2: （2）逾期应收账款 | J2: （2）逾期应收账款 | K2: （2）逾期应收账款 | L2: （2）逾期应收账款 | M2: （2）逾期应收账款 | N2: （2）逾期应收账款 | O2: （2）逾期应收账款 | P2: （2）逾期应收账款 | Q2: （2）逾期应收账款 | R2: （2）逾期应收账款 | S2: （2）逾期应收账款 | T2: （2）逾期应收账款
I3: A.逾期1个月 | J3: 服务费所属期 | K3: B.逾期2-3个月 | L3: 服务费所属期 | M3: C.逾期3个月以上-6个月以内（含6个月） | N3: 服务费所属期 | O3: D.逾期6个月以上-12个月以内（含12个月） | P3: 服务费所属期 | Q3: E.逾期12个月以上 | R3: 服务费所属期 | S3: 小计 | T3: 备注（撤场、合同未签订等）
A4: 陈昌静 | B4: 沪宁区域 | C4: 位军浩 | D4: CF270 | E4: 东大沙塘园食堂 | F4: 月结 | G4: 702920.18 | H4: 0 | I4: 0 | K4: 0 | M4: 0 | O4: 0 | Q4: 702920.18 | R4: 2024-12 | S4: 702920.18 | T4: 2025年6月撤场
A5: 陈昌静 | B5: 沪宁区域 | E5: 部门小计 | G5: 702920.18 | H5: 0 | I5: 0 | K5: 0 | M5: 0 | O5: 0 | Q5: =Q4 -> 702920.18 | S5: 702920.18
A6: 曹伟 | B6: 餐饮五分部 | C6: 位军浩 | D6: CF693 | E6: 甘肃政法大学学生食堂 | F6: 月结 | G6: 94490 | H6: 0 | I6: 0 | K6: 0 | M6: 0 | O6: 0 | Q6: 94490 | R6: 2024-10 | S6: 94490 | T6: 2025年6月撤场
A7: 卜峰 | B7: 兰州区域 | E7: 部门小计 | G7: 94490 | H7: 0 | I7: 0 | K7: 0 | M7: 0 | O7: 0 | Q7: 94490 | S7: 94490
A8: 丁吟春 | B8: 餐饮二分部 | C8: 位军浩 | D8: CF180 | E8: 高新区一初中食堂（珠江路校区） | F8: 月结、学期 | G8: 79752.5 | H8: 0 | I8: 0 | K8: 0 | M8: 0 | O8: 0 | Q8: 79752.5 | R8: 2024-06,2024-10,2024-11,2024-12 | S8: 79752.5
A9: 丁吟春 | B9: 高新区中学区域 | D9: CF179 | E9: 高新区一中食堂（科技城校区） | F9: 月结、学期 | G9: 135638.48 | H9: 0 | I9: 0 | K9: 0 | M9: 0 | O9: 0 | Q9: 135638.48 | R9: 2024-07 | S9: 135638.48
A10: 丁吟春 | B10: 高新区中学区域 | E10: 部门小计 | G10: =SUM(G8:G9) -> 215390.98 | H10: 0 | I10: 0 | K10: 0 | M10: 0 | O10: =O8 -> 0 | Q10: =SUM(Q8:Q9) -> 215390.98 | S10: =SUM(S8:S9) -> 215390.98
A11: 餐饮总、分、子公司等合计 | G11: =G7+G5+G10 -> 1012801.2 | H11: =H7+H5+H10 -> 0 | I11: =I7+I5+I10 -> 0 | J11: =J7+J5+J10 -> 0 | K11: =K7+K5+K10 -> 0 | L11: =L7+L5+L10 -> 0 | M11: =M7+M5+M10 -> 0 | N11: =N7+N5+N10 -> 0 | ... S11: =S7+S5+S10 -> 1012801.2
S14: 填报：财务部（收入核算科）
S15: 复核：谢苗苗
S16: =汇总表!J12 -> 日期：2026/9/4

Sheet 2025年度
A1: 2025年度科桥餐饮公司应收账款统计表 （时间：截至2026.8.31） 金额：元 | B1: 餐饮公司应收账款统计表 | C1: 餐饮公司应收账款统计表 | D1: 餐饮公司应收账款统计表 | E1: 餐饮公司应收账款统计表 | F1: 餐饮公司应收账款统计表 | G1: 餐饮公司应收账款统计表 | H1: 餐饮公司应收账款统计表 | I1: 餐饮公司应收账款统计表 | J1: 餐饮公司应收账款统计表 | K1: 餐饮公司应收账款统计表 | L1: 餐饮公司应收账款统计表 | M1: 餐饮公司应收账款统计表 | N1: 餐饮公司应收账款统计表 | O1: 餐饮公司应收账款统计表 | P1: 餐饮公司应收账款统计表 | Q1: 餐饮公司应收账款统计表 | R1: 餐饮公司应收账款统计表 | S1: 餐饮公司应收账款统计表 | T1: 餐饮公司应收账款统计表
A2: 分部经理 | B2: 分部 | C2: 会计责任人 | D2: 项目编码 | E2: 项目名称 | F2: 合同结算周期（月付、双月付或季付、半年付、年付、一次性等）（考核金合同结束一次性结算、考核金次月结算等） | G2: 应收金额 合计（1）+（2） | H2: （1）正常应收账款 | I2: （2）逾期应收账款 | J2: （2）逾期应收账款 | K2: （2）逾期应收账款 | L2: （2）逾期应收账款 | M2: （2）逾期应收账款 | N2: （2）逾期应收账款 | O2: （2）逾期应收账款 | P2: （2）逾期应收账款 | Q2: （2）逾期应收账款 | R2: （2）逾期应收账款 | S2: （2）逾期应收账款 | T2: （2）逾期应收账款
I3: A.逾期1个月 | J3: 服务费所属期 | K3: B.逾期2-3个月 | L3: 服务费所属期 | M3: C.逾期3个月以上-6个月以内（含6个月） | N3: 服务费所属期 | O3: D.逾期6个月以上-12个月以内（含12个月） | P3: 服务费所属期 | Q3: E.逾期12个月以上 | R3: 服务费所属期 | S3: 小计 | T3: 备注（撤场、合同未签订等）
A4: 陈昌静 | B4: 沪宁区域 | C4: 位军浩 | D4: CF270 | E4: 东大沙塘园食堂 | F4: 月结 | G4: 5247022.4 | H4: 0 | I4: 0 | K4: 0 | M4: 0 | O4: 5247022.4 | P4: 2025-02,2025-03,2025-04,2025-05,2025-06 | Q4: 0 | S4: =O4+M4+K4+I4 -> 5247022.4 | T4: 2025年6月撤场
E5: 部门小计 | G5: =SUM(G4:G4) -> 5247022.4 | H5: =SUM(H4:H4) -> 0 | I5: =SUM(I4:I4) -> 0 | K5: =SUM(K4:K4) -> 0 | M5: =SUM(M4:M4) -> 0 | O5: =SUM(O4:O4) -> 5247022.4 | Q5: =SUM(Q4:Q4) -> 0 | S5: =O5+M5+K5+I5 -> 5247022.4
C6: 位军浩 | D6: CF474 | E6: 安工大七食堂 | F6: 月结 | G6: 1503 | H6: 0 | I6: 0 | K6: 0 | M6: 0 | O6: 1503 | P6: 2025-09,2025-10 | Q6: 0 | S6: =O6+M6+K6+I6 -> 1503
E7: 部门小计 | G7: =SUM(G6:G6) -> 1503 | H7: =SUM(H6:H6) -> 0 | I7: =SUM(I6:I6) -> 0 | K7: =SUM(K6:K6) -> 0 | M7: =SUM(M6:M6) -> 0 | N7: =SUM(N6:N6) -> 0 | O7: =SUM(O6:O6) -> 1503 | P7: =SUM(P6:P6) -> 0 | Q7: =SUM(Q6:Q6) -> 0 | R7: =SUM(R6:R6) -> 0 | S7: =SUM(S6:S6) -> 1503
A8: 丁吟春 | B8: 餐饮二分部 | C8: 位军浩 | D8: CF180 | E8: 高新区一初中食堂（珠江路校区） | F8: 月结、学期 | G8: 122329.23 | H8: 0 | I8: 0 | K8: 0 | M8: 122329.23 | N8: 2025-11,2025-12 | O8: 0 | Q8: 0 | S8: =O8+M8+K8+I8 -> 122329.23
C9: 谢苗苗 | D9: CF140 | E9: 西浦大学太仓校区食堂 | F9: 月结 | G9: 880 | H9: 0 | I9: 0 | K9: 0 | M9: 0 | O9: 880 | P9: 2025-11 | Q9: 0 | S9: =O9+M9+K9+I9 -> 880
C10: 位军浩 | D10: CF160 | E10: 高新区实验高中食堂（金山路校区） | F10: 月结、学期 | G10: 1720058.4 | H10: 0 | I10: 0 | K10: 0 | M10: =200000+438539.1 -> 638539.1 | N10: 2025-11,2025-12 | O10: 1081519.4 | P10: 2025-06,2025-07,2025-08,2025-09,2025-10 | Q10: 0 | S10: =O10+M10+K10+I10 -> 1720058.4
C11: 位军浩 | D11: CF174 | E11: 高新区实验高中食堂（科技城校区） | F11: 月结、学期 | G11: 663072.08 | H11: 0 | I11: 0 | K11: 0 | M11: 463072.08 | N11: 2025-11,2025-12 | O11: 200000 | P11: 2025-10 | Q11: 0 | S11: =O11+M11+K11+I11 -> 663072.08
E12: 部门小计 | G12: =SUM(G8:G11) -> 2506339.8 | H12: =SUM(H8:H11) -> 0 | I12: =SUM(I8:I11) -> 0 | K12: =SUM(K8:K11) -> 0 | M12: =SUM(M8:M11) -> 1223940.4 | N12: =SUM(N8:N11) -> 0 | O12: =SUM(O8:O11) -> 1282399.4 | P12: =SUM(P8:P11) -> 0 | Q12: =SUM(Q8:Q11) -> 0 | R12: =SUM(R8:R11) -> 0 | S12: =SUM(S8:S11) -> 2506339.8
A13: 卜峰 | B13: 餐饮三分部 | C13: 位军浩 | D13: CF190 | E13: 苏旅财食堂 | F13: 月结 | G13: 78484.24 | H13: 0 | I13: 0 | K13: 0 | M13: 0 | O13: 78484.24 | P13: 2025-11 | Q13: 0 | S13: 78484.24
E14: 部门小计 | G14: =SUM(G13:G13) -> 78484.24 | H14: =SUM(H13:H13) -> 0 | I14: =SUM(I13:I13) -> 0 | K14: =SUM(K13:K13) -> 0 | M14: =SUM(M13:M13) -> 0 | N14: =SUM(N13:N13) -> 0 | O14: =SUM(O13:O13) -> 78484.24 | P14: =SUM(P13:P13) -> 0 | Q14: =SUM(Q13:Q13) -> 0 | R14: =SUM(R13:R13) -> 0 | S14: =SUM(S13:S13) -> 78484.24
A15: 曹伟 | B15: 餐饮五分部 | C15: 位军浩 | D15: CF120 | E15: 苏大独墅湖一食堂 | F15: 月结 | G15: 2675 | H15: 0 | I15: 0 | K15: 0 | M15: 2315 | N15: 2025-11,2025-12 | O15: 360 | P15: 2025-07 | Q15: 0 | S15: 2675
C16: 位军浩 | D16: CF102 | E16: 苏大东区四食堂 | F16: 月结 | G16: 110 | H16: 0 | I16: 0 | K16: 0 | M16: 110 | N16: 2025-12 | O16: 0 | Q16: 0 | S16: 110
C17: 位军浩 | D17: CF134 | E17: 苏大独墅湖五食堂 | F17: 月结 | G17: 8179 | H17: 0 | I17: 0 | K17: 0 | M17: 300 | N17: 2025-11 | O17: 7879 | P17: 2025-09,2025-10 | Q17: 0 | S17: 8179
C18: 位军浩 | D18: CF693 | E18: 甘肃政法大学学生食堂 | F18: 月结 | G18: 13200 | H18: 0 | I18: 0 | K18: 0 | M18: 0 | O18: 13200 | P18: 2025-06 | Q18: 0 | S18: 57560
C19: 位军浩 | D19: CF108 | E19: 苏大北区六食堂 | F19: 月结 | G19: 3155 | H19: 0 | I19: 0 | K19: 0 | M19: 0 | O19: 3155 | P19: 2025-12 | Q19: 0 | S19: 3155
C20: 位军浩 | D20: CF107 | E20: 苏大东区教工食堂 | F20: 月结 | G20: 82022.4 | H20: 0 | I20: 0 | K20: 0 | M20: 41011.2 | N20: 2025-12 | O20: 41011.2 | P20: 2025-11 | Q20: 0 | S20: 82022.4
C21: 位军浩 | D21: CF122 | E21: 苏大独墅湖六食堂 | F21: 月结 | G21: 885 | H21: 0 | I21: 0 | K21: 0 | M21: 885 | N21: 2025-12 | O21: 0 | Q21: 0 | S21: 885
E22: 部门小计 | G22: =SUM(G15:G21) -> 110226.4 | H22: =SUM(H15:H21) -> 0 | I22: =SUM(I15:I21) -> 0 | J22: =SUM(J15:J21) -> 0 | K22: =SUM(K15:K21) -> 0 | L22: =SUM(L15:L21) -> 0 | M22: =SUM(M15:M21) -> 44621.2 | N22: =SUM(N15:N21) -> 0 | ... S22: =SUM(S15:S21) -> 154586.4
A23: 吕磊 | B23: 餐饮六分部 | C23: 位军浩 | D23: CF479 | E23: 江苏交通第一学生食堂 | F23: 月结 | G23: 50 | H23: 0 | I23: 0 | K23: 0 | M23: 50 | N23: 2025-12 | O23: 0 | Q23: 0 | S23: =O23+M23+K23+I23 -> 50
C24: 位军浩 | D24: CF475 | E24: 国科大南京学院食堂 | F24: 月结（考核按年度结算） | G24: 254644.5 | H24: 0 | I24: 0 | K24: 0 | M24: =254644.5-O24 -> 236286 | N24: 2025-11,2025-12 | O24: 18358.5 | P24: 2025-10 | Q24: 0 | S24: =O24+M24+K24+I24 -> 254644.5
C25: 位军浩 | D25: CF191 | E25: 苏州旭辉彩园餐厅 | F25: 月结 | G25: 1046805.7 | H25: 0 | I25: 0 | K25: 0 | M25: 353039.18 | N25: 2025-11,2025-12 | O25: 693766.47 | P25: 2025-06,2025-07,2025-09,2025-10 | Q25: 0 | S25: =O25+M25+K25+I25 -> 1046805.7
C26: 谢苗苗 | D26: CF275 | E26: 南大苏州校区西区二食堂 | F26: 月结 | G26: 5410 | H26: 0 | I26: 0 | K26: 0 | M26: 0 | O26: 4410 | P26: 2025-11 | Q26: 1000 | R26: 2025-12 | S26: 5410
E27: 部门小计 | G27: =SUM(G23:G26) -> 1306910.1 | H27: =SUM(H23:H26) -> 0 | I27: =SUM(I23:I26) -> 0 | J27: =SUM(J23:J26) -> 0 | K27: =SUM(K23:K26) -> 0 | L27: =SUM(L23:L26) -> 0 | M27: =SUM(M23:M26) -> 589375.18 | N27: =SUM(N23:N26) -> 0 | ... S27: =SUM(S23:S26) -> 1306910.1
A28: 餐饮总、分、子公司等合计 | G28: =SUM(G4:G27)/2 -> 9250486 | H28: =SUM(H4:H27)/2 -> 0 | I28: =SUM(I4:I27)/2 -> 0 | K28: =SUM(K4:K27)/2 -> 0 | M28: =SUM(M4:M27)/2 -> 1857936.8 | O28: =SUM(O4:O27)/2 -> 7391549.2 | Q28: =SUM(Q4:Q27)/2 -> 1000 | R28: =SUM(R4:R27)/2 -> 0 | S28: =SUM(S4:S27)/2 -> 9294846
S30: 填报：财务部（收入核算科）
S31: 复核：谢苗苗
S32: =汇总表!J12 -> 日期：2026/9/4

Sheet 2026年8月科桥餐饮公司应收账款统计表
A1: 2026年8月科桥餐饮公司应收账款统计表 （时间：截至2026.8.31） 金额：元 | B1: 餐饮公司应收账款统计表 | C1: 餐饮公司应收账款统计表 | D1: 餐饮公司应收账款统计表 | E1: 餐饮公司应收账款统计表 | F1: 餐饮公司应收账款统计表 | G1: 餐饮公司应收账款统计表 | H1: 餐饮公司应收账款统计表 | I1: 餐饮公司应收账款统计表 | J1: 餐饮公司应收账款统计表 | K1: 餐饮公司应收账款统计表 | L1: 餐饮公司应收账款统计表 | M1: 餐饮公司应收账款统计表 | N1: 餐饮公司应收账款统计表 | O1: 餐饮公司应收账款统计表 | P1: 餐饮公司应收账款统计表 | Q1: 餐饮公司应收账款统计表 | R1: 餐饮公司应收账款统计表 | S1: 餐饮公司应收账款统计表 | T1: 餐饮公司应收账款统计表
A2: 分部经理 | B2: 分部 | C2: 会计责任人 | D2: 项目编码 | E2: 项目名称 | F2: 合同结算周期（月付、双月付或季付、半年付、年付、一次性等）（考核金合同结束一次性结算、考核金次月结算等） | G2: 应收金额 合计（1）+（2） | H2: （1）正常应收账款 | I2: （2）逾期应收账款 | J2: （2）逾期应收账款 | K2: （2）逾期应收账款 | L2: （2）逾期应收账款 | M2: （2）逾期应收账款 | N2: （2）逾期应收账款 | O2: （2）逾期应收账款 | P2: （2）逾期应收账款 | Q2: （2）逾期应收账款 | R2: （2）逾期应收账款 | S2: （2）逾期应收账款 | T2: （2）逾期应收账款
I3: A.逾期1个月 | J3: 服务费所属期 | K3: B.逾期2-3个月 | L3: 服务费所属期 | M3: C.逾期3个月以上-6个月以内（含6个月） | N3: 服务费所属期 | O3: D.逾期6个月以上-12个月以内（含12个月） | P3: 服务费所属期 | Q3: E.逾期12个月以上 | R3: 服务费所属期 | S3: 小计 | T3: 备注（撤场、合同未签订等）
A4: 陈昌静 | B4: 餐饮一分部 | C4: 位军浩 | D4: CF142 | E4: 卡特彼勒（吴江）餐厅 | G4: 695917.45 | H4: =G4-S4 -> 684726.74 | K4: 11190.71 | L4: 2026-04 | M4: 0 | O4: 0 | Q4: 0 | S4: =Q4+O4+M4+K4+I4 -> 11190.71
C5: 位军浩 | D5: CF141 | E5: 泰科阳澄湖工厂 | G5: 3162095.8 | H5: =G5-S5 -> 2093483.8 | I5: 523051.37 | J5: 2026-05 | K5: 545560.6 | L5: 2026-04 | M5: 0 | O5: 0 | Q5: 0 | S5: =Q5+O5+M5+K5+I5 -> 1068612
C6: 谢苗苗 | D6: CF139 | E6: 苏州中科新药篮餐厅 | G6: 309130.42 | H6: =G6-S6 -> 291200.92 | I6: 12680 | J6: 2026-06 | K6: 5249.5 | L6: 2026-04,2026-05 | M6: 0 | O6: 0 | Q6: 0 | S6: =Q6+O6+M6+K6+I6 -> 17929.5
C7: 位军浩 | D7: CF138 | E7: 苏州生物产业园三期餐厅 | G7: 455900.44 | H7: =G7-S7 -> 455900.44 | I7: 0 | K7: 0 | M7: 0 | O7: 0 | Q7: 0 | S7: =Q7+O7+M7+K7+I7 -> 0 | T7: 撤场项目
C8: 位军浩 | D8: CF272 | E8: 苏州工学院南一食堂 | G8: 175277.73 | H8: =G8-S8 -> 175277.73 | I8: 0 | K8: 0 | M8: 0 | O8: 0 | Q8: 0 | S8: =Q8+O8+M8+K8+I8 -> 0
C9: 位军浩 | D9: CF127-1 | E9: 泰科老厂餐厅 | G9: 5981139.8 | H9: =G9-S9 -> 4613431.1 | I9: 1366569.2 | J9: 2026-05 | K9: 1139.4 | L9: 2026-03 | O9: 0 | Q9: 0 | S9: =Q9+O9+M9+K9+I9 -> 1367708.6
C10: 位军浩 | D10: CF751 | E10: 国防科大（长沙）食堂 | G10: 1549640.6 | H10: =G10-S10 -> 1420902.5 | I10: 128738.05 | J10: 2026-06 | K10: 0 | M10: 0 | O10: 0 | Q10: 0 | S10: =Q10+O10+M10+K10+I10 -> 128738.05
C11: 位军浩 | D11: CF514 | E11: 昆山康桥培英高级中学食堂 | G11: 568469 | H11: =G11-S11 -> 568469 | I11: 0 | K11: 0 | M11: 0 | O11: 0 | Q11: 0 | S11: =Q11+O11+M11+K11+I11 -> 0
C12: 谢苗苗 | D12: CF481 | E12: 常熟世华高级中学食堂 | G12: 167353.69 | H12: =G12-S12 -> 32920.12 | I12: 134433.57 | J12: 2026-06 | K12: 0 | M12: 0 | O12: 0 | Q12: 0 | S12: =Q12+O12+M12+K12+I12 -> 134433.57
C13: 谢苗苗 | D13: CF478 | E13: 苏州华扬电子餐厅 | G13: 170171.4 | H13: =G13-S13 -> 170171.4 | I13: 0 | K13: 0 | M13: 0 | O13: 0 | Q13: 0 | S13: =Q13+O13+M13+K13+I13 -> 0
C14: 谢苗苗 | D14: CF477 | E14: 上海民航第一食堂 | G14: 664440.39 | H14: =G14-S14 -> 32488.77 | I14: 631951.62 | J14: 2026-06 | K14: 0 | M14: 0 | O14: 0 | Q14: 0 | S14: =Q14+O14+M14+K14+I14 -> 631951.62
C15: 位军浩 | D15: CF474 | E15: 安工大七食堂 | G15: 153914.23 | H15: =G15-S15 -> 151789.23 | I15: 0 | K15: 2125 | L15: 2026-04 | M15: 0 | O15: 0 | Q15: 0 | S15: =Q15+O15+M15+K15+I15 -> 2125
C16: 位军浩 | D16: CF127-3 | E16: 泰科新厂餐厅 | G16: 9396380.9 | H16: =G16-S16 -> 5778569.7 | I16: 1702014 | J16: 2026-05 | K16: 1915797.3 | L16: 2026-04 | M16: 0 | O16: 0 | Q16: 0 | S16: =Q16+O16+M16+K16+I16 -> 3617811.3
E17: 部门小计 | G17: =SUM(G4:G16) -> 23449832 | H17: =SUM(H4:H16) -> 16469331 | I17: =SUM(I4:I16) -> 4499437.8 | J17: =SUM(J4:J16) -> 0 | K17: =SUM(K4:K16) -> 2481062.5 | L17: =SUM(L4:L16) -> 0 | M17: =SUM(M4:M16) -> 0 | N17: =SUM(N4:N16) -> 0 | ... S17: =SUM(S4:S16) -> 6980500.3
A18: 丁吟春 | B18: 餐饮二分部 | C18: 位军浩 | D18: CF453 | E18: 天津大学学四食堂 | G18: 56992.07 | H18: =G18-S18 -> 56992.07 | I18: 0 | K18: 0 | M18: 0 | O18: 0 | Q18: 0 | S18: =Q18+O18+M18+K18+I18 -> 0
C19: 位军浩 | D19: CF183 | E19: 中医科苏州新校区食堂 | G19: 1177757.3 | H19: =G19-S19 -> 747005.63 | I19: 211436.22 | J19: 2026-06 | K19: 218115.48 | L19: 2026-05 | M19: 1200 | N19: 2026-03 | O19: 0 | Q19: 0 | S19: =Q19+O19+M19+K19+I19 -> 430751.7
C20: 谢苗苗 | D20: CF140 | E20: 西浦大学太仓校区食堂 | G20: 139100 | H20: =G20-S20 -> 68370 | I20: 27180 | J20: 2026-06 | K20: 38930 | L20: 2026-04,2026-05 | M20: 4620 | N20: 2026-03 | O20: 0 | Q20: 0 | S20: =Q20+O20+M20+K20+I20 -> 70730
C21: 位军浩 | D21: CF700 | E21: 北理工长三角研究院(嘉兴)食堂 | G21: 547034.13 | H21: =G21-S21 -> 546559.13 | I21: 475 | J21: 2026-08 | K21: 0 | M21: 0 | O21: 0 | Q21: 0 | S21: =Q21+O21+M21+K21+I21 -> 475
C22: 谢苗苗 | D22: CF125 | E22: 西浦大学宏愿南食堂 | G22: 55810 | H22: =G22-S22 -> 23990 | I22: 30820 | J22: 2026-06 | K22: 1000 | L22: 2026-04 | M22: 0 | O22: 0 | Q22: 0 | S22: =Q22+O22+M22+K22+I22 -> 31820
C23: 位军浩 | D23: CF513 | E23: 天津大学学三食堂 | G23: 45261.49 | H23: =G23-S23 -> 45261.49 | I23: 0 | K23: 0 | M23: 0 | O23: 0 | Q23: 0 | S23: =Q23+O23+M23+K23+I23 -> 0
C24: 谢苗苗 | D24: CF137 | E24: 西浦大学宏愿北食堂 | G24: 2250 | H24: =G24-S24 -> 0 | I24: 0 | K24: 0 | M24: 2250 | N24: 2026-03 | O24: 0 | Q24: 0 | S24: =Q24+O24+M24+K24+I24 -> 2250
C25: 位军浩 | D25: CF516 | E25: 苏州北美高中食堂 | G25: 92052.3 | H25: =G25-S25 -> 92052.3 | I25: 0 | K25: 0 | M25: 0 | O25: 0 | Q25: 0 | S25: =Q25+O25+M25+K25+I25 -> 0
C26: 位军浩 | D26: CF179 | E26: 高新区一中食堂（科技城校区） | G26: 1633292.7 | H26: =G26-S26 -> 221222.87 | I26: 252084.56 | J26: 2026-06 | K26: 518663.51 | L26: 2026-04,2026-05 | M26: 641321.74 | N26: 2026-01,2026-02,2026-03 | O26: 0 | Q26: 0 | S26: =Q26+O26+M26+K26+I26 -> 1412069.8
C27: 位军浩 | D27: CF177 | E27: 高新区实验初中食堂（锦峰路校区） | G27: 637643.7 | H27: =G27-S27 -> 8498.08 | I27: 158143.93 | J27: 2026-06 | K27: 305792.27 | L27: 2026-04,2026-05 | M27: 165209.42 | N27: 2026-02,2026-03 | O27: 0 | Q27: 0 | S27: =Q27+O27+M27+K27+I27 -> 629145.62
C28: 位军浩 | D28: CF175 | E28: 高新区实验初中食堂（金山路校区） | G28: 978747.48 | H28: =G28-S28 -> 0 | I28: 207907.15 | J28: 2026-06 | K28: 575545.84 | L28: 2026-04,2026-05 | M28: 195294.49 | N28: 2026-02 | O28: 0 | Q28: 0 | S28: =Q28+O28+M28+K28+I28 -> 978747.48
C29: 位军浩 | D29: CF174 | E29: 高新区实验高中食堂（科技城校区） | G29: 1316435.5 | H29: =G29-S29 -> 115329.06 | I29: 202737.48 | J29: 2026-06 | K29: 471450.12 | L29: 2026-04,2026-05 | M29: 526918.88 | N29: 2026-01,2026-02,2026-03 | O29: 0 | Q29: 0 | S29: =Q29+O29+M29+K29+I29 -> 1201106.5
C30: 位军浩 | D30: CF180 | E30: 高新区一初中食堂（珠江路校区） | G30: 649824.32 | H30: =G30-S30 -> 0 | I30: 118414.8 | J30: 2026-06 | K30: 243599.88 | L30: 2026-04,2026-05 | M30: 287809.64 | N30: 2026-01,2026-02,2026-03 | O30: 0 | Q30: 0 | S30: =Q30+O30+M30+K30+I30 -> 649824.32
C31: 位军浩 | D31: CF450 | E31: 天津大学学二食堂 | G31: 825228.26 | H31: =G31-S31 -> 774655.26 | I31: 0 | K31: 50573 | L31: 2026-04 | M31: 0 | O31: 0 | Q31: 0 | S31: =Q31+O31+M31+K31+I31 -> 50573
C32: 位军浩 | D32: CF364 | E32: 江苏航运思本轩二楼食堂 | G32: 263506.66 | H32: =G32-S32 -> 244762.37 | I32: 14590.46 | J32: 2026-06 | K32: 4153.83 | L32: 2026-05 | M32: 0 | O32: 0 | Q32: 0 | S32: =Q32+O32+M32+K32+I32 -> 18744.29
C33: 位军浩 | D33: CF363 | E33: 南通大学启东一期食堂一楼 | G33: 158624.28 | H33: =G33-S33 -> 158624.28 | I33: 0 | K33: 0 | M33: 0 | O33: 0 | Q33: 0 | S33: =Q33+O33+M33+K33+I33 -> 0
C34: 位军浩 | D34: CF360 | E34: 南通师专新校区食堂 | G34: 23213 | H34: =G34-S34 -> 1230 | I34: 11408 | J34: 2026-06 | K34: 10575 | L34: 2026-04,2026-05 | M34: 0 | O34: 0 | Q34: 0 | S34: =Q34+O34+M34+K34+I34 -> 21983
C35: 谢苗苗 | D35: CF181 | E35: 中科大苏州研究院食堂 | G35: 136147.53 | H35: =G35-S35 -> 135297.53 | I35: 850 | J35: 2026-06 | K35: 0 | M35: 0 | O35: 0 | Q35: 0 | S35: =Q35+O35+M35+K35+I35 -> 850
C36: 谢苗苗 | D36: CF182 | E36: 无锡工艺第二食堂 | G36: 2355 | H36: =G36-S36 -> 0 | I36: 2355 | J36: 2026-06 | K36: 0 | M36: 0 | O36: 0 | Q36: 0 | S36: =Q36+O36+M36+K36+I36 -> 2355
C37: 位军浩 | D37: CF173 | E37: 高新区一中食堂（汾湖路校区） | G37: 1612785.2 | H37: =G37-S37 -> 266367.81 | I37: 286449.27 | J37: 2026-06 | K37: 570892.05 | L37: 2026-04,2026-05 | M37: 489076.08 | N37: 2026-01,2026-02,2026-03 | O37: 0 | Q37: 0 | S37: =Q37+O37+M37+K37+I37 -> 1346417.4
C38: 位军浩 | D38: CF160 | E38: 高新区实验高中食堂（金山路校区） | G38: 1394910.2 | H38: =G38-S38 -> 111638.94 | I38: 233941.93 | J38: 2026-06 | K38: 454952.18 | L38: 2026-04,2026-05 | M38: 594377.13 | N38: 2026-01,2026-02,2026-03 | O38: 0 | Q38: 0 | S38: =Q38+O38+M38+K38+I38 -> 1283271.2
E39: 部门小计 | G39: =SUM(G18:G38) -> 11748971 | H39: =SUM(H18:H38) -> 3617856.8 | I39: =SUM(I18:I38) -> 1758793.8 | J39: =SUM(J18:J38) -> 0 | K39: =SUM(K18:K38) -> 3464243.2 | L39: =SUM(L18:L38) -> 0 | M39: =SUM(M18:M38) -> 2908077.4 | N39: =SUM(N18:N38) -> 0 | ... T39: =SUM(T18:T38) -> 0
A40: 卜峰 | B40: 餐饮三分部 | C40: 谢苗苗 | D40: CF126 | E40: 西浦附校食堂 | G40: 1008090.2 | H40: =G40-S40 -> 707830.2 | I40: 291510 | J40: 2026-06 | K40: 8750 | L40: 2026-05 | M40: 0 | O40: 0 | Q40: 0 | S40: =Q40+O40+M40+K40+I40 -> 300260
...

Sheet Sheet1
A1: 摘要 | B1: 项目编码 | C1: 项目编码1 | D1: 项目名称 | E1: 方向 | F1: 期初余额 | G1: 本期借方 | H1: 本期贷方 | I1: 借方累计 | J1: 贷方累计 | K1: 方向 | L1: 期末余额
B2: 0300 | C2: =LEFT(B2,5) -> 0300 | D2: 【项目：科桥餐饮公司】 | E2: 贷 | F2: 1299729.8 | J2: 212000 | K2: 贷 | R2: 项目编码1 | S2: 求和项:期末余额
B3: 0300-1 | C3: =LEFT(B3,5) -> 0300- | D3: 【项目：科桥餐饮公司（内部交易）】 | E3: 借 | F3: 1017963.9 | G3: 391930.65 | H3: 112507.42 | I3: 2336262.7 | J3: 7263858.8 | K3: 借 | R3: 0300
B4: C001 | C4: =LEFT(B4,5) -> C001 | D4: 【项目：餐饮综合部】 | E4: 平 | G4: 900 | I4: 1199.4 | J4: 299.4 | K4: 借 | R4: 0300-
B5: CF101 | C5: =LEFT(B5,5) -> CF101 | D5: 【项目：苏大本部方塔食堂】 | E5: 平 | I5: 2065637.2 | J5: 2065637.2 | K5: 平 | R5: C001
B6: CF102 | C6: =LEFT(B6,5) -> CF102 | D6: 【项目：苏大东区四食堂】 | E6: 借 | F6: 200 | I6: 2385938.7 | J6: 2385738.7 | K6: 借 | L6: 200 | R6: CF101 | S6: 558916.38
B7: CF102-1 | C7: =LEFT(B7,5) -> CF102 | D7: 【项目：苏大东区四食堂（快餐）】 | E7: 平 | J7: 800 | K7: 平 | R7: CF102 | S7: 152926.07
B8: CF107 | C8: =LEFT(B8,5) -> CF107 | D8: 【项目：苏大东区教工食堂】 | E8: 平 | I8: 529905.26 | J8: 529905.26 | K8: 平 | R8: CF107 | S8: 369100.8
B9: CF108 | C9: =LEFT(B9,5) -> CF108 | D9: 【项目：苏大北区六食堂】 | E9: 借 | F9: 4647 | H9: 2782 | I9: 1481247.3 | J9: 1489267.3 | K9: 借 | L9: 1865 | R9: CF108 | S9: 235575.17
B10: CF120 | C10: =LEFT(B10,5) -> CF120 | D10: 【项目：苏大独墅湖一食堂】 | E10: 借 | F10: 150 | I10: 3350251.8 | J10: 3350101.8 | K10: 借 | L10: 150 | R10: CF120 | S10: 369664.05
B11: CF120-1 | C11: =LEFT(B11,5) -> CF120 | D11: 【项目：苏大独墅湖一食堂（快餐）】 | E11: 借 | F11: 2160 | J11: 640794.14 | K11: 借 | L11: 2160 | R11: CF121 | S11: 272619.13
B12: CF121 | C12: =LEFT(B12,5) -> CF121 | D12: 【项目：苏大独墅湖二食堂】 | E12: 平 | I12: 2740413.9 | J12: 2740413.9 | K12: 平 | R12: CF122 | S12: 428645.95
B13: CF122 | C13: =LEFT(B13,5) -> CF122 | D13: 【项目：苏大独墅湖六食堂】 | E13: 平 | I13: 2164861.5 | J13: 2164861.5 | K13: 平 | R13: CF124
B14: CF122-1 | C14: =LEFT(B14,5) -> CF122 | D14: 【项目：苏大独墅湖六食堂（快餐）】 | E14: 平 | I14: -660 | K14: 平 | R14: CF125 | S14: 55810
B15: CF122-3 | C15: =LEFT(B15,5) -> CF122 | D15: 【项目：苏大独墅湖六食堂（强责）】 | E15: 平 | I15: 300 | J15: 300 | K15: 平 | R15: CF126 | S15: 1008090.2
B16: CF124 | C16: =LEFT(B16,5) -> CF124 | D16: 【项目：苏州评弹学院食堂】 | E16: 平 | I16: 1830619.5 | J16: 1830619.5 | K16: 平 | R16: CF127 | S16: 15377521
B17: CF125 | C17: =LEFT(B17,5) -> CF125 | D17: 【项目：西浦大学宏愿南食堂】 | E17: 借 | F17: 60950 | G17: 171692.17 | H17: 176832.17 | I17: 3492840.9 | J17: 3471460.9 | K17: 借 | L17: 55810 | R17: CF134 | S17: 122872.9
B18: CF125-2 | C18: =LEFT(B18,5) -> CF125 | D18: 【项目：西浦大学宏愿南食堂（分组作业）】 | E18: 平 | I18: -2475 | J18: 71712 | K18: 平 | R18: CF137 | S18: 2250
B19: CF126 | C19: =LEFT(B19,5) -> CF126 | D19: 【项目：西浦附校食堂】 | E19: 借 | F19: 1622030.1 | G19: 204529.1 | H19: 1335539.2 | I19: 11918149 | J19: 12922395 | K19: 借 | L19: 491020 | R19: CF138 | S19: 455900.44
B20: CF127-1 | C20: =LEFT(B20,5) -> CF127 | D20: 【项目：泰科老厂餐厅】 | E20: 借 | F20: 2903243 | G20: 1631816 | H20: 29149.31 | I20: 12117081 | J20: 10605020 | K20: 借 | L20: 4505909.7 | R20: CF139 | S20: 309130.42
B21: CF127-3 | C21: =LEFT(B21,5) -> CF127 | D21: 【项目：泰科新厂餐厅】 | E21: 借 | F21: 5562171.7 | G21: 2024661.9 | H21: 56979.2 | I21: 14984874 | J21: 11156365 | K21: 借 | L21: 7529854.3 | R21: CF140 | S21: 139980
B22: CF134 | C22: =LEFT(B22,5) -> CF134 | D22: 【项目：苏大独墅湖五食堂】 | E22: 平 | I22: 1967704.9 | J22: 1967704.9 | K22: 平 | R22: CF141 | S22: 3162095.8
B23: CF134-1 | C23: =LEFT(B23,5) -> CF134 | D23: 【项目：苏大独墅湖五食堂（快餐）】 | E23: 借 | F23: 8329 | I23: -60 | J23: 918 | K23: 借 | L23: 8329 | R23: CF142 | S23: 695917.45
B24: CF137 | C24: =LEFT(B24,5) -> CF137 | D24: 【项目：西浦大学宏愿北食堂】 | E24: 借 | F24: 2250 | I24: 2149525.1 | J24: 2147275.1 | K24: 借 | L24: 2250 | R24: CF160 | S24: 3114968.6
B25: CF137-1 | C25: =LEFT(B25,5) -> CF137 | D25: 【项目：西浦大学宏愿北食堂（快餐）】 | E25: 平 | K25: 平 | R25: CF173 | S25: 2858080
B26: CF138 | C26: =LEFT(B26,5) -> CF138 | D26: 【项目：苏州生物产业园三期餐厅】 | E26: 借 | F26: 27509.51 | G26: 17426.01 | H26: 14948.2 | I26: 1404764.8 | J26: 1385856.4 | K26: 借 | L26: 29987.32 | R26: CF174 | S26: 1979507.6
B27: CF139 | C27: =LEFT(B27,5) -> CF139 | D27: 【项目：苏州中科新药篮餐厅】 | E27: 借 | F27: 57827.8 | G27: 211008.13 | H27: 182854.99 | I27: 1512518.7 | J27: 1551102.1 | K27: 借 | L27: 85980.94 | R27: CF175 | S27: 978747.48
B28: CF140 | C28: =LEFT(B28,5) -> CF140 | D28: 【项目：西浦大学太仓校区食堂】 | E28: 借 | F28: 232885 | G28: 200819.63 | H28: 293724.63 | I28: 1322100.5 | J28: 1219104.5 | K28: 借 | L28: 139980 | R28: CF177 | S28: 637643.7
B29: CF140-1 | C29: =LEFT(B29,5) -> CF140 | D29: 【项目：西浦大学太仓校区食堂（快餐）】 | E29: 平 | K29: 平 | R29: CF179 | S29: 2993474.3
B30: CF141 | C30: =LEFT(B30,5) -> CF141 | D30: 【项目：泰科阳澄湖工厂】 | E30: 借 | F30: 1708329 | G30: 729012.44 | H30: 85245.73 | I30: 5734117.4 | J30: 5450681.7 | K30: 借 | L30: 2352095.7 | R30: CF180 | S30: 866164.05
B31: CF142 | C31: =LEFT(B31,5) -> CF142 | D31: 【项目：卡特彼勒（吴江）餐厅】 | E31: 借 | F31: 1150008.8 | H31: 454091.34 | I31: 2934195.2 | J31: 3647106.2 | K31: 借 | L31: 695917.45 | R31: CF181 | S31: 136147.53
B32: CF160 | C32: =LEFT(B32,5) -> CF160 | D32: 【项目：高新区实验高中食堂（金山路校区）】 | E32: 借 | F32: 1720058.4 | I32: 1320058.4 | J32: 994349.12 | K32: 借 | L32: 1720058.4 | R32: CF182 | S32: 2355
B33: CF173 | C33: =LEFT(B33,5) -> CF173 | D33: 【项目：高新区一中食堂（汾湖路校区）】 | E33: 借 | F33: 755109.32 | H33: 266033.24 | I33: 3569933.8 | J33: 3080857.7 | K33: 借 | L33: 489076.08 | R33: CF183 | S33: 1177757.3
B34: CF174 | C34: =LEFT(B34,5) -> CF174 | D34: 【项目：高新区实验高中食堂（科技城校区）】 | E34: 借 | F34: 663072.08 | I34: 2270847.9 | J34: 1807775.8 | K34: 借 | L34: 663072.08 | R34: CF190 | S34: 265481.78
B35: CF175 | C35: =LEFT(B35,5) -> CF175 | D35: 【项目：高新区实验初中食堂（金山路校区）】 | E35: 借 | F35: 770840.33 | I35: 1877311 | J35: 1106470.7 | K35: 借 | L35: 770840.33 | R35: CF191 | S35: 1591774.7
B36: CF177 | C36: =LEFT(B36,5) -> CF177 | D36: 【项目：高新区实验初中食堂（锦峰路校区）】 | E36: 平 | I36: 448248.16 | J36: 456268.16 | K36: 平 | R36: CF212 | S36: 473637.69
B37: CF179 | C37: =LEFT(B37,5) -> CF179 | D37: 【项目：高新区一中食堂（科技城校区）】 | E37: 借 | F37: 641321.74 | I37: 2953440.5 | J37: 2312118.8 | K37: 借 | L37: 641321.74 | R37: CF213 | S37: 1267774.6
B38: CF180 | C38: =LEFT(B38,5) -> CF180 | D38: 【项目：高新区一初中食堂（珠江路校区）】 | E38: 借 | F38: 626132.1 | I38: 746635.48 | J38: 410885.14 | K38: 借 | L38: 626132.1 | R38: CF251 | S38: 75411.48
B39: CF181 | C39: =LEFT(B39,5) -> CF181 | D39: 【项目：中科大苏州研究院食堂】 | E39: 借 | F39: 1120 | G39: 154787.69 | H39: 154677.69 | I39: 1224233.2 | J39: 1223888.2 | K39: 借 | L39: 1230 | R39: CF270 | S39: 5949942.6
B40: CF182 | C40: =LEFT(B40,5) -> CF182 | D40: 【项目：无锡工艺第二食堂】 | E40: 平 | I40: 1928343.4 | J40: 1930923.4 | K40: 平 | R40: CF272 | S40: 175277.73
...

Sheet Sheet2
A1: 项目编码1 | B1: 求和项:期末余额
A2: CF101 | B2: 558916.38
A3: CF102 | B3: 152926.07
A4: CF107 | B4: 369100.8
A5: CF108 | B5: 235575.17
A6: CF120 | B6: 369664.05
A7: CF121 | B7: 272619.13
A8: CF122 | B8: 428645.95
A9: CF124
A10: CF125 | B10: 55810
A11: CF126 | B11: 1008090.2
A12: CF127 | B12: 15377521
A13: CF134 | B13: 122872.9
A14: CF137 | B14: 2250
A15: CF138 | B15: 455900.44
A16: CF139 | B16: 309130.42
A17: CF140 | B17: 139980
A18: CF141 | B18: 3162095.8
A19: CF142 | B19: 695917.45
A20: CF160 | B20: 3114968.6
A21: CF173 | B21: 2858080
... A40: CF293 | B40: 619613.94
A41: CF310
A42: CF320 | B42: 1107336.2
A43: CF341 | B43: 45619.85
A44: CF360 | B44: 23213
A45: CF363 | B45: 158624.28
A46: CF364 | B46: 263506.66
A47: CF450 | B47: 825228.26
A48: CF452
A49: CF453 | B49: 56992.07
A50: CF474 | B50: 155417.23
A51: CF475 | B51: 1655835.5
A52: CF477 | B52: 664440.39
A53: CF478 | B53: 170171.4
A54: CF479 | B54: 6360
A55: CF480
A56: CF481 | B56: 167353.69
A57: CF513 | B57: 45261.49
A58: CF514 | B58: 568469
...

Sheet Sheet3
A1: 分管领导 | B1: 区域 | C1: 项目经理 | D1: 会计责任人 | E1: 项目编码 | F1: 项目编码1 | G1: 项目名称 | H1: 应收金额 合计（1）+（2）
A2: 卜峰 | B2: 餐饮三分部 | E2: CF190 | F2: =LEFT(E2,5) -> CF190 | G2: 苏旅财食堂 | H2: 265481.78 | I2: =VLOOKUP(F2,Sheet2!$A$2:$B$73,2,0) -> 265481.78 | J2: =H2-I2 -> 0
A3: 卜峰 | B3: 餐饮三分部 | E3: CF251 | F3: =LEFT(E3,5) -> CF251 | G3: 苏州职大第二学生食堂 | H3: 75411.48 | I3: =VLOOKUP(F3,Sheet2!$A$2:$B$73,2,0) -> 75411.48 | J3: =H3-I3 -> 0
A4: 卜峰 | B4: 餐饮三分部 | E4: CF641 | F4: =LEFT(E4,5) -> CF641 | G4: 中山大学北学二食堂 | H4: 81565.72 | I4: =VLOOKUP(F4,Sheet2!$A$2:$B$73,2,0) -> 81565.72 | J4: =H4-I4 -> 0
A5: 卜峰 | B5: 餐饮三分部 | E5: CF699 | F5: =LEFT(E5,5) -> CF699 | G5: 徐医大第一食堂 | H5: 250663.05 | I5: =VLOOKUP(F5,Sheet2!$A$2:$B$73,2,0) -> 250663.05 | J5: =H5-I5 -> 0
A6: 卜峰 | B6: 餐饮三分部 | E6: CF780 | F6: =LEFT(E6,5) -> CF780 | G6: 吉建大二食堂 | H6: 1443341.2 | I6: =VLOOKUP(F6,Sheet2!$A$2:$B$73,2,0) -> 1443341.2 | J6: =H6-I6 -> 0
A7: 卜峰 | B7: 餐饮三分部 | E7: CF126 | F7: =LEFT(E7,5) -> CF126 | G7: 西浦附校食堂 | H7: 1008090.2 | I7: =VLOOKUP(F7,Sheet2!$A$2:$B$73,2,0) -> 1008090.2 | J7: =H7-I7 -> 0
A8: 卜峰 | B8: 餐饮三分部 | E8: CF781 | F8: =LEFT(E8,5) -> CF781 | G8: 苏食院第一学生食堂 | H8: 269325.34 | I8: =VLOOKUP(F8,Sheet2!$A$2:$B$73,2,0) -> 269875.84 | J8: =H8-I8 -> -550.5 | L8: 268430.34
A9: 卜峰 | B9: 餐饮三分部 | E9: CF320 | F9: =LEFT(E9,5) -> CF320 | G9: 江苏财经梅园食堂 | H9: 1107336.2 | I9: =VLOOKUP(F9,Sheet2!$A$2:$B$73,2,0) -> 1107336.2 | J9: =H9-I9 -> 0 | L9: =H8-L8 -> 895
A10: 卜峰 | B10: 餐饮三分部 | E10: CF276 | F10: =LEFT(E10,5) -> CF276 | G10: 苏州经贸第二食堂 | H10: 185287.96 | I10: =VLOOKUP(F10,Sheet2!$A$2:$B$73,2,0) -> 185287.96 | J10: =H10-I10 -> 0
A11: 卜峰 | B11: 餐饮三分部 | D11: 小计 | F11: =LEFT(E11,5) | H11: 1779795.4 | I11: =VLOOKUP(F11,Sheet2!$A$2:$B$73,2,0) -> #N/A | J11: =H11-I11 -> #N/A
A12: 曹伟 | B12: 餐饮五分部 | E12: CF134 | F12: =LEFT(E12,5) -> CF134 | G12: 苏大独墅湖五食堂 | H12: 122872.9 | I12: =VLOOKUP(F12,Sheet2!$A$2:$B$73,2,0) -> 122872.9 | J12: =H12-I12 -> 0
A13: 曹伟 | B13: 餐饮五分部 | E13: CF694 | F13: =LEFT(E13,5) -> CF694 | G13: 兰理工彭家坪北村食堂 | H13: 60757.7 | I13: =VLOOKUP(F13,Sheet2!$A$2:$B$73,2,0) -> 60757.7 | J13: =H13-I13 -> 0
A14: 曹伟 | B14: 餐饮五分部 | E14: CF101 | F14: =LEFT(E14,5) -> CF101 | G14: 苏大本部方塔食堂 | H14: 558916.38 | I14: =VLOOKUP(F14,Sheet2!$A$2:$B$73,2,0) -> 558916.38 | J14: =H14-I14 -> 0
A15: 曹伟 | B15: 餐饮五分部 | E15: CF102 | F15: =LEFT(E15,5) -> CF102 | G15: 苏大东区四食堂 | H15: 152926.07 | I15: =VLOOKUP(F15,Sheet2!$A$2:$B$73,2,0) -> 152926.07 | J15: =H15-I15 -> 0
A16: 曹伟 | B16: 餐饮五分部 | E16: CF693 | F16: =LEFT(E16,5) -> CF693 | G16: 甘肃政法大学学生食堂 | H16: 107690 | I16: =VLOOKUP(F16,Sheet2!$A$2:$B$73,2,0) -> 107690 | J16: =H16-I16 -> 0
A17: 曹伟 | B17: 餐饮五分部 | E17: CF107 | F17: =LEFT(E17,5) -> CF107 | G17: 苏大东区教工食堂 | H17: 369100.8 | I17: =VLOOKUP(F17,Sheet2!$A$2:$B$73,2,0) -> 369100.8 | J17: =H17-I17 -> 0
A18: 曹伟 | B18: 餐饮五分部 | E18: CF620 | F18: =LEFT(E18,5) -> CF620 | G18: 山西大学B6食堂三层 | H18: 87133.66 | I18: =VLOOKUP(F18,Sheet2!$A$2:$B$73,2,0) -> 87133.66 | J18: =H18-I18 -> 0
A19: 曹伟 | B19: 餐饮五分部 | E19: CF697 | F19: =LEFT(E19,5) -> CF697 | G19: 兰交大百苑二楼食堂 | H19: 413796.21 | I19: =VLOOKUP(F19,Sheet2!$A$2:$B$73,2,0) -> 413796.21 | J19: =H19-I19 -> 0
A20: 曹伟 | B20: 餐饮五分部 | E20: CF122 | F20: =LEFT(E20,5) -> CF122 | G20: 苏大独墅湖六食堂 | H20: 428645.95 | I20: =VLOOKUP(F20,Sheet2!$A$2:$B$73,2,0) -> 428645.95 | J20: =H20-I20 -> 0
A21: 曹伟 | B21: 餐饮五分部 | E21: CF121 | F21: =LEFT(E21,5) -> CF121 | G21: 苏大独墅湖二食堂 | H21: 272619.13 | I21: =VLOOKUP(F21,Sheet2!$A$2:$B$73,2,0) -> 272619.13 | J21: =H21-I21 -> 0
A22: 曹伟 | B22: 餐饮五分部 | E22: CF120 | F22: =LEFT(E22,5) -> CF120 | G22: 苏大独墅湖一食堂 | H22: 369664.05 | I22: =VLOOKUP(F22,Sheet2!$A$2:$B$73,2,0) -> 369664.05 | J22: =H22-I22 -> 0
A23: 曹伟 | B23: 餐饮五分部 | E23: CF698 | F23: =LEFT(E23,5) -> CF698 | G23: 兰理工兰工坪校区第一食堂 | H23: 717428.96 | I23: =VLOOKUP(F23,Sheet2!$A$2:$B$73,2,0) -> 717428.96 | J23: =H23-I23 -> 0
... A25: 曹伟 | B25: 餐饮五分部 | E25: CF696 | F25: =LEFT(E25,5) -> CF696 | G25: 甘肃省气象局餐厅 | H25: 158922 | I25: =VLOOKUP(F25,Sheet2!$A$2:$B$73,2,0) -> 158922 | J25: =H25-I25 -> 0
A26: 曹伟 | B26: 餐饮五分部 | D26: 小计 | F26: =LEFT(E26,5) | H26: 841570.32 | I26: =VLOOKUP(F26,Sheet2!$A$2:$B$73,2,0) -> #N/A | J26: =H26-I26 -> #N/A
A27: 陈昌静 | B27: 餐饮一分部 | E27: CF142 | F27: =LEFT(E27,5) -> CF142 | G27: 卡特彼勒（吴江）餐厅 | H27: 695917.45 | I27: =VLOOKUP(F27,Sheet2!$A$2:$B$73,2,0) -> 695917.45 | J27: =H27-I27 -> 0
A28: 陈昌静 | B28: 餐饮一分部 | E28: CF141 | F28: =LEFT(E28,5) -> CF141 | G28: 泰科阳澄湖工厂 | H28: 3162095.8 | I28: =VLOOKUP(F28,Sheet2!$A$2:$B$73,2,0) -> 3162095.8 | J28: =H28-I28 -> 0
A29: 陈昌静 | B29: 餐饮一分部 | E29: CF139 | F29: =LEFT(E29,5) -> CF139 | G29: 苏州中科新药篮餐厅 | H29: 309130.42 | I29: =VLOOKUP(F29,Sheet2!$A$2:$B$73,2,0) -> 309130.42 | J29: =H29-I29 -> 0
A30: 陈昌静 | B30: 餐饮一分部 | E30: CF138 | F30: =LEFT(E30,5) -> CF138 | G30: 苏州生物产业园三期餐厅 | H30: 455900.44 | I30: =VLOOKUP(F30,Sheet2!$A$2:$B$73,2,0) -> 455900.44 | J30: =H30-I30 -> 0
A31: 陈昌静 | B31: 餐饮一分部 | E31: CF127-1 | F31: =LEFT(E31,5) -> CF127 | G31: 泰科老厂餐厅 | H31: 5981139.8 | I31: =VLOOKUP(F31,Sheet2!$A$2:$B$73,2,0) -> 15377521 | J31: =H31-I31 -> -9396380.9
A32: 陈昌静 | B32: 餐饮一分部 | E32: CF127-3 | F32: =LEFT(E32,5) -> CF127 | G32: 泰科新厂餐厅 | H32: 9396380.9 | I32: =VLOOKUP(F32,Sheet2!$A$2:$B$73,2,0) -> 15377521 | J32: =H32-I32 -> -5981139.8
A33: 陈昌静 | B33: 餐饮一分部 | E33: CF751 | F33: =LEFT(E33,5) -> CF751 | G33: 国防科大（长沙）食堂 | H33: 1549640.6 | I33: =VLOOKUP(F33,Sheet2!$A$2:$B$73,2,0) -> 1549640.6 | J33: =H33-I33 -> 0
A34: 陈昌静 | B34: 餐饮一分部 | E34: CF514 | F34: =LEFT(E34,5) -> CF514 | G34: 昆山康桥培英高级中学食堂 | H34: 568469 | I34: =VLOOKUP(F34,Sheet2!$A$2:$B$73,2,0) -> 568469 | J34: =H34-I34 -> 0
A35: 陈昌静 | B35: 餐饮一分部 | E35: CF481 | F35: =LEFT(E35,5) -> CF481 | G35: 常熟世华高级中学食堂 | H35: 167353.69 | I35: =VLOOKUP(F35,Sheet2!$A$2:$B$73,2,0) -> 167353.69 | J35: =H35-I35 -> 0
A36: 陈昌静 | B36: 餐饮一分部 | E36: CF478 | F36: =LEFT(E36,5) -> CF478 | G36: 苏州华扬电子餐厅 | H36: 170171.4 | I36: =VLOOKUP(F36,Sheet2!$A$2:$B$73,2,0) -> 170171.4 | J36: =H36-I36 -> 0
A37: 陈昌静 | B37: 餐饮一分部 | E37: CF477 | F37: =LEFT(E37,5) -> CF477 | G37: 上海民航第一食堂 | H37: 664440.39 | I37: =VLOOKUP(F37,Sheet2!$A$2:$B$73,2,0) -> 664440.39 | J37: =H37-I37 -> 0
A38: 陈昌静 | B38: 餐饮一分部 | E38: CF474 | F38: =LEFT(E38,5) -> CF474 | G38: 安工大七食堂 | H38: 155417.23 | I38: =VLOOKUP(F38,Sheet2!$A$2:$B$73,2,0) -> 155417.23 | J38: =H38-I38 -> 0
A39: 陈昌静 | B39: 餐饮一分部 | E39: CF272 | F39: =LEFT(E39,5) -> CF272 | G39: 苏州工学院南一食堂 | H39: 175277.73 | I39: =VLOOKUP(F39,Sheet2!$A$2:$B$73,2,0) -> 175277.73 | J39: =H39-I39 -> 0
A40: 陈昌静 | B40: 餐饮一分部 | D40: 小计 | F40: =LEFT(E40,5) | H40: 7157281 | I40: =VLOOKUP(F40,Sheet2!$A$2:$B$73,2,0) -> #N/A | J40: =H40-I40 -> #N/A
A41: 陈昌静 | B41: 沪宁区域 | C41: 吕磊 | E41: CF270 | F41: =LEFT(E41,5) -> CF270 | G41: 东大沙塘园食堂 | H41: 5949942.6 | I41: =VLOOKUP(F41,Sheet2!$A$2:$B$73,2,0) -> 5949942.6 | J41: =H41-I41 -> 0
...
